Workbook

Sheet Rohdaten
A1: RunID | B1: Komponente | C1: Aktionsklasse | D1: LoggingProfil | E1: Wiederholung | F1: BAMStatus | G1: SID | H1: ExecutablePath | I1: ExecutionTimeUTC | J1: ExecutionTimeLocal | K1: KeyPath | L1: SourceHive
A2: PS-A1-P0-R01 | B2: PS | C2: A1 | D2: P0 | E2: R01 | F2: Kein passender BAM-Eintrag | L2: E:\KAPE_Runs\PS-A1-P0\PS-A1-P0-R01\KAPE\C\Windows\System32\config\SYSTEM
A3: PS-A1-P0-R02 | B3: PS | C3: A1 | D3: P0 | E3: R02 | F3: Kein passender BAM-Eintrag | L3: E:\KAPE_Runs\PS-A1-P0\PS-A1-P0-R02\KAPE\C\Windows\System32\config\SYSTEM
A4: PS-A1-P0-R03 | B4: PS | C4: A1 | D4: P0 | E4: R03 | F4: Kein passender BAM-Eintrag | L4: E:\KAPE_Runs\PS-A1-P0\PS-A1-P0-R03\KAPE\C\Windows\System32\config\SYSTEM
A5: PS-A1-P1-R01 | B5: PS | C5: A1 | D5: P1 | E5: R01 | F5: Kein passender BAM-Eintrag | L5: E:\KAPE_Runs\PS-A1-P1\PS-A1-P1-R01\KAPE\C\Windows\System32\config\SYSTEM
A6: PS-A1-P1-R02 | B6: PS | C6: A1 | D6: P1 | E6: R02 | F6: Kein passender BAM-Eintrag | L6: E:\KAPE_Runs\PS-A1-P1\PS-A1-P1-R02\KAPE\C\Windows\System32\config\SYSTEM
A7: PS-A1-P1-R03 | B7: PS | C7: A1 | D7: P1 | E7: R03 | F7: Kein passender BAM-Eintrag | L7: E:\KAPE_Runs\PS-A1-P1\PS-A1-P1-R03\KAPE\C\Windows\System32\config\SYSTEM
A8: PS-A1-P2-R01 | B8: PS | C8: A1 | D8: P2 | E8: R01 | F8: BAM-Eintrag vorhanden | G8: S-1-5-21-4065717026-3980475814-3063633344-1001 | H8: \Device\HarddiskVolume3\Windows\System32\WindowsPowerShell\v1.0\powershell.exe | I8: 2026-08-21 13:44:00.9766578 | J8: 2026-08-21 15:44:00.9766578 | K8: ROOT\ControlSet001\Services\bam\State\UserSettings\S-1-5-21-4065717026-3980475814-3063633344-1001 | L8: E:\KAPE_Runs\PS-A1-P2\PS-A1-P2-R01\KAPE\C\Windows\System32\config\SYSTEM
A9: PS-A1-P2-R02 | B9: PS | C9: A1 | D9: P2 | E9: R02 | F9: BAM-Eintrag vorhanden | G9: S-1-5-21-4065717026-3980475814-3063633344-1001 | H9: \Device\HarddiskVolume3\Windows\System32\WindowsPowerShell\v1.0\powershell.exe | I9: 2026-08-21 13:53:44.7579311 | J9: 2026-08-21 15:53:44.7579311 | K9: ROOT\ControlSet001\Services\bam\State\UserSettings\S-1-5-21-4065717026-3980475814-3063633344-1001 | L9: E:\KAPE_Runs\PS-A1-P2\PS-A1-P2-R02\KAPE\C\Windows\System32\config\SYSTEM
A10: PS-A1-P2-R03 | B10: PS | C10: A1 | D10: P2 | E10: R03 | F10: BAM-Eintrag vorhanden | G10: S-1-5-21-4065717026-3980475814-3063633344-1001 | H10: \Device\HarddiskVolume3\Windows\System32\WindowsPowerShell\v1.0\powershell.exe | I10: 2026-08-02 14:09:05.9260236 | J10: 2026-08-02 16:09:05.9260236 | K10: ROOT\ControlSet001\Services\bam\State\UserSettings\S-1-5-21-4065717026-3980475814-3063633344-1001 | L10: E:\KAPE_Runs\PS-A1-P2\PS-A1-P2-R03\KAPE\C\Windows\System32\config\SYSTEM
A11: PS-A2-P0-R01 | B11: PS | C11: A2 | D11: P0 | E11: R01 | F11: Kein passender BAM-Eintrag | L11: E:\KAPE_Runs\PS-A2-P0\PS-A2-P0-R01\KAPE\C\Windows\System32\config\SYSTEM
A12: PS-A2-P0-R02 | B12: PS | C12: A2 | D12: P0 | E12: R02 | F12: Kein passender BAM-Eintrag | L12: E:\KAPE_Runs\PS-A2-P0\PS-A2-P0-R02\KAPE\C\Windows\System32\config\SYSTEM
A13: PS-A2-P0-R03 | B13: PS | C13: A2 | D13: P0 | E13: R03 | F13: Kein passender BAM-Eintrag | L13: E:\KAPE_Runs\PS-A2-P0\PS-A2-P0-R03\KAPE\C\Windows\System32\config\SYSTEM
A14: PS-A2-P1-R01 | B14: PS | C14: A2 | D14: P1 | E14: R01 | F14: Kein passender BAM-Eintrag | L14: E:\KAPE_Runs\PS-A2-P1\PS-A2-P1-R01\KAPE\C\Windows\System32\config\SYSTEM
A15: PS-A2-P1-R02 | B15: PS | C15: A2 | D15: P1 | E15: R02 | F15: Kein passender BAM-Eintrag | L15: E:\KAPE_Runs\PS-A2-P1\PS-A2-P1-R02\KAPE\C\Windows\System32\config\SYSTEM
A16: PS-A2-P1-R03 | B16: PS | C16: A2 | D16: P1 | E16: R03 | F16: Kein passender BAM-Eintrag | L16: E:\KAPE_Runs\PS-A2-P1\PS-A2-P1-R03\KAPE\C\Windows\System32\config\SYSTEM
A17: PS-A2-P2-R01 | B17: PS | C17: A2 | D17: P2 | E17: R01 | F17: BAM-Eintrag vorhanden | G17: S-1-5-21-4065717026-3980475814-3063633344-1001 | H17: \Device\HarddiskVolume3\Windows\System32\WindowsPowerShell\v1.0\powershell.exe | I17: 2026-08-21 14:09:30.9206787 | J17: 2026-08-21 16:09:30.9206787 | K17: ROOT\ControlSet001\Services\bam\State\UserSettings\S-1-5-21-4065717026-3980475814-3063633344-1001 | L17: E:\KAPE_Runs\PS-A2-P2\PS-A2-P2-R01\KAPE\C\Windows\System32\config\SYSTEM
A18: PS-A2-P2-R02 | B18: PS | C18: A2 | D18: P2 | E18: R02 | F18: BAM-Eintrag vorhanden | G18: S-1-5-21-4065717026-3980475814-3063633344-1001 | H18: \Device\HarddiskVolume3\Windows\System32\WindowsPowerShell\v1.0\powershell.exe | I18: 2026-08-21 14:18:32.4965953 | J18: 2026-08-21 16:18:32.4965953 | K18: ROOT\ControlSet001\Services\bam\State\UserSettings\S-1-5-21-4065717026-3980475814-3063633344-1001 | L18: E:\KAPE_Runs\PS-A2-P2\PS-A2-P2-R02\KAPE\C\Windows\System32\config\SYSTEM
A19: PS-A2-P2-R03 | B19: PS | C19: A2 | D19: P2 | E19: R03 | F19: BAM-Eintrag vorhanden | G19: S-1-5-21-4065717026-3980475814-3063633344-1001 | H19: \Device\HarddiskVolume3\Windows\System32\WindowsPowerShell\v1.0\powershell.exe | I19: 2026-08-21 14:29:22.3492797 | J19: 2026-08-21 16:29:22.3492797 | K19: ROOT\ControlSet001\Services\bam\State\UserSettings\S-1-5-21-4065717026-3980475814-3063633344-1001 | L19: E:\KAPE_Runs\PS-A2-P2\PS-A2-P2-R03\KAPE\C\Windows\System32\config\SYSTEM
A20: MSHTA-A1-P0-R01 | B20: MSHTA | C20: A1 | D20: P0 | E20: R01 | F20: BAM-Eintrag vorhanden | G20: S-1-5-21-4065717026-3980475814-3063633344-1001 | H20: \Device\HarddiskVolume3\Windows\System32\mshta.exe | I20: 2026-08-21 09:21:11.3171217 | J20: 2026-08-21 11:21:11.3171217 | K20: ROOT\ControlSet001\Services\bam\State\UserSettings\S-1-5-21-4065717026-3980475814-3063633344-1001 | L20: E:\KAPE_Runs\MSHTA-A1-P0\MSHTA-A1-P0-R01\KAPE\C\Windows\System32\config\SYSTEM
A21: MSHTA-A1-P0-R02 | B21: MSHTA | C21: A1 | D21: P0 | E21: R02 | F21: BAM-Eintrag vorhanden | G21: S-1-5-21-4065717026-3980475814-3063633344-1001 | H21: \Device\HarddiskVolume3\Windows\System32\mshta.exe | I21: 2026-08-21 09:28:03.6549092 | J21: 2026-08-21 11:28:03.6549092 | K21: ROOT\ControlSet001\Services\bam\State\UserSettings\S-1-5-21-4065717026-3980475814-3063633344-1001 | L21: E:\KAPE_Runs\MSHTA-A1-P0\MSHTA-A1-P0-R02\KAPE\C\Windows\System32\config\SYSTEM
A22: MSHTA-A1-P0-R03 | B22: MSHTA | C22: A1 | D22: P0 | E22: R03 | F22: BAM-Eintrag vorhanden | G22: S-1-5-21-4065717026-3980475814-3063633344-1001 | H22: \Device\HarddiskVolume3\Windows\System32\mshta.exe | I22: 2026-08-21 09:38:24.9834132 | J22: 2026-08-21 11:38:24.9834132 | K22: ROOT\ControlSet001\Services\bam\State\UserSettings\S-1-5-21-4065717026-3980475814-3063633344-1001 | L22: E:\KAPE_Runs\MSHTA-A1-P0\MSHTA-A1-P0-R03\KAPE\C\Windows\System32\config\SYSTEM
A23: MSHTA-A1-P1-R01 | B23: MSHTA | C23: A1 | D23: P1 | E23: R01 | F23: BAM-Eintrag vorhanden | G23: S-1-5-21-4065717026-3980475814-3063633344-1001 | H23: \Device\HarddiskVolume3\Windows\System32\mshta.exe | I23: 2026-08-21 11:38:19.3617324 | J23: 2026-08-21 13:38:19.3617324 | K23: ROOT\ControlSet001\Services\bam\State\UserSettings\S-1-5-21-4065717026-3980475814-3063633344-1001 | L23: E:\KAPE_Runs\MSHTA-A1-P1\MSHTA-A1-P1-R01\KAPE\C\Windows\System32\config\SYSTEM
A24: MSHTA-A1-P1-R02 | B24: MSHTA | C24: A1 | D24: P1 | E24: R02 | F24: BAM-Eintrag vorhanden | G24: S-1-5-21-4065717026-3980475814-3063633344-1001 | H24: \Device\HarddiskVolume3\Windows\System32\mshta.exe | I24: 2026-08-21 11:42:59.7603601 | J24: 2026-08-21 13:42:59.7603601 | K24: ROOT\ControlSet001\Services\bam\State\UserSettings\S-1-5-21-4065717026-3980475814-3063633344-1001 | L24: E:\KAPE_Runs\MSHTA-A1-P1\MSHTA-A1-P1-R02\KAPE\C\Windows\System32\config\SYSTEM
A25: MSHTA-A1-P1-R03 | B25: MSHTA | C25: A1 | D25: P1 | E25: R03 | F25: BAM-Eintrag vorhanden | G25: S-1-5-21-4065717026-3980475814-3063633344-1001 | H25: \Device\HarddiskVolume3\Windows\System32\mshta.exe | I25: 2026-08-21 11:47:40.6212335 | J25: 2026-08-21 13:47:40.6212335 | K25: ROOT\ControlSet001\Services\bam\State\UserSettings\S-1-5-21-4065717026-3980475814-3063633344-1001 | L25: E:\KAPE_Runs\MSHTA-A1-P1\MSHTA-A1-P1-R03\KAPE\C\Windows\System32\config\SYSTEM
A26: MSHTA-A1-P2-R01 | B26: MSHTA | C26: A1 | D26: P2 | E26: R01 | F26: BAM-Eintrag vorhanden | G26: S-1-5-21-4065717026-3980475814-3063633344-1001 | H26: \Device\HarddiskVolume3\Windows\System32\mshta.exe | I26: 2026-08-21 14:39:29.8815922 | J26: 2026-08-21 16:39:29.8815922 | K26: ROOT\ControlSet001\Services\bam\State\UserSettings\S-1-5-21-4065717026-3980475814-3063633344-1001 | L26: E:\KAPE_Runs\MSHTA-A1-P2\MSHTA-A1-P2-R01\KAPE\C\Windows\System32\config\SYSTEM
A27: MSHTA-A1-P2-R02 | B27: MSHTA | C27: A1 | D27: P2 | E27: R02 | F27: BAM-Eintrag vorhanden | G27: S-1-5-21-4065717026-3980475814-3063633344-1001 | H27: \Device\HarddiskVolume3\Windows\System32\mshta.exe | I27: 2026-08-21 14:56:25.3975755 | J27: 2026-08-21 16:56:25.3975755 | K27: ROOT\ControlSet001\Services\bam\State\UserSettings\S-1-5-21-4065717026-3980475814-3063633344-1001 | L27: E:\KAPE_Runs\MSHTA-A1-P2\MSHTA-A1-P2-R02\KAPE\C\Windows\System32\config\SYSTEM
A28: MSHTA-A1-P2-R03 | B28: MSHTA | C28: A1 | D28: P2 | E28: R03 | F28: BAM-Eintrag vorhanden | G28: S-1-5-21-4065717026-3980475814-3063633344-1001 | H28: \Device\HarddiskVolume3\Windows\System32\mshta.exe | I28: 2026-08-21 15:27:41.6032404 | J28: 2026-08-21 17:27:41.6032404 | K28: ROOT\ControlSet001\Services\bam\State\UserSettings\S-1-5-21-4065717026-3980475814-3063633344-1001 | L28: E:\KAPE_Runs\MSHTA-A1-P2\MSHTA-A1-P2-R03\KAPE\C\Windows\System32\config\SYSTEM
... A37: MSHTA-A2-P2-R03 | B37: MSHTA | C37: A2 | D37: P2 | E37: R03 | F37: BAM-Eintrag vorhanden | G37: S-1-5-21-4065717026-3980475814-3063633344-1001 | H37: \Device\HarddiskVolume3\Windows\System32\mshta.exe | I37: 2026-08-21 15:51:32.7566131 | J37: 2026-08-21 17:51:32.7566131 | K37: ROOT\ControlSet001\Services\bam\State\UserSettings\S-1-5-21-4065717026-3980475814-3063633344-1001 | L37: E:\KAPE_Runs\MSHTA-A2-P2\MSHTA-A2-P2-R03\KAPE\C\Windows\System32\config\SYSTEM
A38: REG-A1-P0-R01 | B38: REG | C38: A1 | D38: P0 | E38: R01 | F38: Kein passender BAM-Eintrag | L38: E:\KAPE_Runs\REG-A1-P0\REG-A1-P0-R01\KAPE\C\Windows\System32\config\SYSTEM
A39: REG-A1-P0-R02 | B39: REG | C39: A1 | D39: P0 | E39: R02 | F39: Kein passender BAM-Eintrag | L39: E:\KAPE_Runs\REG-A1-P0\REG-A1-P0-R02\KAPE\C\Windows\System32\config\SYSTEM
A40: REG-A1-P0-R03 | B40: REG | C40: A1 | D40: P0 | E40: R03 | F40: Kein passender BAM-Eintrag | L40: E:\KAPE_Runs\REG-A1-P0\REG-A1-P0-R03\KAPE\C\Windows\System32\config\SYSTEM
A41: REG-A1-P1-R01 | B41: REG | C41: A1 | D41: P1 | E41: R01 | F41: Kein passender BAM-Eintrag | L41: E:\KAPE_Runs\REG-A1-P1\REG-A1-P1-R01\KAPE\C\Windows\System32\config\SYSTEM
A42: REG-A1-P1-R02 | B42: REG | C42: A1 | D42: P1 | E42: R02 | F42: Kein passender BAM-Eintrag | L42: E:\KAPE_Runs\REG-A1-P1\REG-A1-P1-R02\KAPE\C\Windows\System32\config\SYSTEM
A43: REG-A1-P1-R03 | B43: REG | C43: A1 | D43: P1 | E43: R03 | F43: Kein passender BAM-Eintrag | L43: E:\KAPE_Runs\REG-A1-P1\REG-A1-P1-R03\KAPE\C\Windows\System32\config\SYSTEM
A44: REG-A1-P2-R01 | B44: REG | C44: A1 | D44: P2 | E44: R01 | F44: Kein passender BAM-Eintrag | L44: E:\KAPE_Runs\REG-A1-P2\REG-A1-P2-R01\KAPE\C\Windows\System32\config\SYSTEM
A45: REG-A1-P2-R02 | B45: REG | C45: A1 | D45: P2 | E45: R02 | F45: Kein passender BAM-Eintrag | L45: E:\KAPE_Runs\REG-A1-P2\REG-A1-P2-R02\KAPE\C\Windows\System32\config\SYSTEM
A46: REG-A1-P2-R03 | B46: REG | C46: A1 | D46: P2 | E46: R03 | F46: Kein passender BAM-Eintrag | L46: E:\KAPE_Runs\REG-A1-P2\REG-A1-P2-R03\KAPE\C\Windows\System32\config\SYSTEM
A47: REG-A2-P0-R01 | B47: REG | C47: A2 | D47: P0 | E47: R01 | F47: Kein passender BAM-Eintrag | L47: E:\KAPE_Runs\REG-A2-P0\REG-A2-P0-R01\KAPE\C\Windows\System32\config\SYSTEM
A48: REG-A2-P0-R02 | B48: REG | C48: A2 | D48: P0 | E48: R02 | F48: Kein passender BAM-Eintrag | L48: E:\KAPE_Runs\REG-A2-P0\REG-A2-P0-R02\KAPE\C\Windows\System32\config\SYSTEM
...

Sheet Run-Level bewertet
A1: Run-ID | B1: Komponente | C1: Aktionsklasse | D1: LoggingProfil | E1: Wiederholung | F1: BAM-Status (bewertet) | G1: SID | H1: ExecutablePath | I1: ExecutionTime UTC | J1: ExecutionTime lokal (+02:00) | K1: RunStart lokal (+02:00) | L1: ProcessEnd lokal (+02:00) | M1: Nachweis | N1: K | O1: T | P1: U | Q1: A | R1: H | S1: Kurzbegründung
A2: PS-A1-P0-R01 | B2: PowerShell | C2: A1 | D2: P0 | E2: R01 | F2: Kein passender BAM-Eintrag | K2: 46255.437 | L2: 46255.437 | M2: =IF(F2="BAM-Treffer im Execution-Zeitraum",1,0) -> 0 | N2: =IF(M2=1,2,"-") -> - | O2: =IF(M2=1,2,"-") -> - | P2: =IF(M2=1,1,"-") -> - | Q2: =IF(M2=1,0,"-") -> - | R2: =IF(M2=1,0,"-") -> - | S2: =IF(M2=1,"Run-spezifischer BAM-Befund: Executable-Pfad und ExecutionTime ordnen die Zielkomponente direkt dem Lauf zu; Benutzerkontext liegt über die SID vor. Kommandozeile, Parent-Prozess und konkrete A1/A2-Handlung werden nicht dokumentiert.",IF(F2="Kein passender BAM-Eintrag","Kein passender BAM-Eintrag der untersuchten Komponente; daher kein run-spezifischer BAM-Nachweis.",IF(F2="BAM-Eintrag vorhanden, Ausführungszeit nicht im Execution-Zeitraum","BAM-Eintrag vorhanden, die ExecutionTime gehört jedoch nicht zum betrachteten Experimentlauf; daher kein run-spezifischer Nachweis.","BAM-Eintrag vorhanden, aber der Referenzzeitraum des Runs ist in der bereitgestellten RunTabelle nicht verfügbar."))) -> Kein passender BAM-Eintrag der untersuchten Komponente; daher kein run-spezifischer BAM-Nachweis.
A3: PS-A1-P0-R02 | B3: PowerShell | C3: A1 | D3: P0 | E3: R02 | F3: Kein passender BAM-Eintrag | K3: 46255.449 | L3: 46255.449 | M3: =IF(F3="BAM-Treffer im Execution-Zeitraum",1,0) -> 0 | N3: =IF(M3=1,2,"-") -> - | O3: =IF(M3=1,2,"-") -> - | P3: =IF(M3=1,1,"-") -> - | Q3: =IF(M3=1,0,"-") -> - | R3: =IF(M3=1,0,"-") -> - | S3: =IF(M3=1,"Run-spezifischer BAM-Befund: Executable-Pfad und ExecutionTime ordnen die Zielkomponente direkt dem Lauf zu; Benutzerkontext liegt über die SID vor. Kommandozeile, Parent-Prozess und konkrete A1/A2-Handlung werden nicht dokumentiert.",IF(F3="Kein passender BAM-Eintrag","Kein passender BAM-Eintrag der untersuchten Komponente; daher kein run-spezifischer BAM-Nachweis.",IF(F3="BAM-Eintrag vorhanden, Ausführungszeit nicht im Execution-Zeitraum","BAM-Eintrag vorhanden, die ExecutionTime gehört jedoch nicht zum betrachteten Experimentlauf; daher kein run-spezifischer Nachweis.","BAM-Eintrag vorhanden, aber der Referenzzeitraum des Runs ist in der bereitgestellten RunTabelle nicht verfügbar."))) -> Kein passender BAM-Eintrag der untersuchten Komponente; daher kein run-spezifischer BAM-Nachweis.
A4: PS-A1-P0-R03 | B4: PowerShell | C4: A1 | D4: P0 | E4: R03 | F4: Kein passender BAM-Eintrag | K4: 46255.452 | L4: 46255.452 | M4: =IF(F4="BAM-Treffer im Execution-Zeitraum",1,0) -> 0 | N4: =IF(M4=1,2,"-") -> - | O4: =IF(M4=1,2,"-") -> - | P4: =IF(M4=1,1,"-") -> - | Q4: =IF(M4=1,0,"-") -> - | R4: =IF(M4=1,0,"-") -> - | S4: =IF(M4=1,"Run-spezifischer BAM-Befund: Executable-Pfad und ExecutionTime ordnen die Zielkomponente direkt dem Lauf zu; Benutzerkontext liegt über die SID vor. Kommandozeile, Parent-Prozess und konkrete A1/A2-Handlung werden nicht dokumentiert.",IF(F4="Kein passender BAM-Eintrag","Kein passender BAM-Eintrag der untersuchten Komponente; daher kein run-spezifischer BAM-Nachweis.",IF(F4="BAM-Eintrag vorhanden, Ausführungszeit nicht im Execution-Zeitraum","BAM-Eintrag vorhanden, die ExecutionTime gehört jedoch nicht zum betrachteten Experimentlauf; daher kein run-spezifischer Nachweis.","BAM-Eintrag vorhanden, aber der Referenzzeitraum des Runs ist in der bereitgestellten RunTabelle nicht verfügbar."))) -> Kein passender BAM-Eintrag der untersuchten Komponente; daher kein run-spezifischer BAM-Nachweis.
A5: PS-A1-P1-R01 | B5: PowerShell | C5: A1 | D5: P1 | E5: R01 | F5: Kein passender BAM-Eintrag | K5: 46255.545 | L5: 46255.545 | M5: =IF(F5="BAM-Treffer im Execution-Zeitraum",1,0) -> 0 | N5: =IF(M5=1,2,"-") -> - | O5: =IF(M5=1,2,"-") -> - | P5: =IF(M5=1,1,"-") -> - | Q5: =IF(M5=1,0,"-") -> - | R5: =IF(M5=1,0,"-") -> - | S5: =IF(M5=1,"Run-spezifischer BAM-Befund: Executable-Pfad und ExecutionTime ordnen die Zielkomponente direkt dem Lauf zu; Benutzerkontext liegt über die SID vor. Kommandozeile, Parent-Prozess und konkrete A1/A2-Handlung werden nicht dokumentiert.",IF(F5="Kein passender BAM-Eintrag","Kein passender BAM-Eintrag der untersuchten Komponente; daher kein run-spezifischer BAM-Nachweis.",IF(F5="BAM-Eintrag vorhanden, Ausführungszeit nicht im Execution-Zeitraum","BAM-Eintrag vorhanden, die ExecutionTime gehört jedoch nicht zum betrachteten Experimentlauf; daher kein run-spezifischer Nachweis.","BAM-Eintrag vorhanden, aber der Referenzzeitraum des Runs ist in der bereitgestellten RunTabelle nicht verfügbar."))) -> Kein passender BAM-Eintrag der untersuchten Komponente; daher kein run-spezifischer BAM-Nachweis.
A6: PS-A1-P1-R02 | B6: PowerShell | C6: A1 | D6: P1 | E6: R02 | F6: Kein passender BAM-Eintrag | K6: 46255.549 | L6: 46255.549 | M6: =IF(F6="BAM-Treffer im Execution-Zeitraum",1,0) -> 0 | N6: =IF(M6=1,2,"-") -> - | O6: =IF(M6=1,2,"-") -> - | P6: =IF(M6=1,1,"-") -> - | Q6: =IF(M6=1,0,"-") -> - | R6: =IF(M6=1,0,"-") -> - | S6: =IF(M6=1,"Run-spezifischer BAM-Befund: Executable-Pfad und ExecutionTime ordnen die Zielkomponente direkt dem Lauf zu; Benutzerkontext liegt über die SID vor. Kommandozeile, Parent-Prozess und konkrete A1/A2-Handlung werden nicht dokumentiert.",IF(F6="Kein passender BAM-Eintrag","Kein passender BAM-Eintrag der untersuchten Komponente; daher kein run-spezifischer BAM-Nachweis.",IF(F6="BAM-Eintrag vorhanden, Ausführungszeit nicht im Execution-Zeitraum","BAM-Eintrag vorhanden, die ExecutionTime gehört jedoch nicht zum betrachteten Experimentlauf; daher kein run-spezifischer Nachweis.","BAM-Eintrag vorhanden, aber der Referenzzeitraum des Runs ist in der bereitgestellten RunTabelle nicht verfügbar."))) -> Kein passender BAM-Eintrag der untersuchten Komponente; daher kein run-spezifischer BAM-Nachweis.
A7: PS-A1-P1-R03 | B7: PowerShell | C7: A1 | D7: P1 | E7: R03 | F7: Kein passender BAM-Eintrag | K7: 46255.555 | L7: 46255.555 | M7: =IF(F7="BAM-Treffer im Execution-Zeitraum",1,0) -> 0 | N7: =IF(M7=1,2,"-") -> - | O7: =IF(M7=1,2,"-") -> - | P7: =IF(M7=1,1,"-") -> - | Q7: =IF(M7=1,0,"-") -> - | R7: =IF(M7=1,0,"-") -> - | S7: =IF(M7=1,"Run-spezifischer BAM-Befund: Executable-Pfad und ExecutionTime ordnen die Zielkomponente direkt dem Lauf zu; Benutzerkontext liegt über die SID vor. Kommandozeile, Parent-Prozess und konkrete A1/A2-Handlung werden nicht dokumentiert.",IF(F7="Kein passender BAM-Eintrag","Kein passender BAM-Eintrag der untersuchten Komponente; daher kein run-spezifischer BAM-Nachweis.",IF(F7="BAM-Eintrag vorhanden, Ausführungszeit nicht im Execution-Zeitraum","BAM-Eintrag vorhanden, die ExecutionTime gehört jedoch nicht zum betrachteten Experimentlauf; daher kein run-spezifischer Nachweis.","BAM-Eintrag vorhanden, aber der Referenzzeitraum des Runs ist in der bereitgestellten RunTabelle nicht verfügbar."))) -> Kein passender BAM-Eintrag der untersuchten Komponente; daher kein run-spezifischer BAM-Nachweis.
A8: PS-A1-P2-R01 | B8: PowerShell | C8: A1 | D8: P2 | E8: R01 | F8: BAM-Treffer im Execution-Zeitraum | G8: S-1-5-21-4065717026-3980475814-3063633344-1001 | H8: \Device\HarddiskVolume3\Windows\System32\WindowsPowerShell\v1.0\powershell.exe | I8: 46255.572 | J8: 46255.656 | K8: 46255.655 | L8: 46255.656 | M8: =IF(F8="BAM-Treffer im Execution-Zeitraum",1,0) -> 1 | N8: =IF(M8=1,2,"-") -> 2 | O8: =IF(M8=1,2,"-") -> 2 | P8: =IF(M8=1,1,"-") -> 1 | Q8: =IF(M8=1,0,"-") -> 0 | R8: =IF(M8=1,0,"-") -> 0 | S8: =IF(M8=1,"Run-spezifischer BAM-Befund: Executable-Pfad und ExecutionTime ordnen die Zielkomponente direkt dem Lauf zu; Benutzerkontext liegt über die SID vor. Kommandozeile, Parent-Prozess und konkrete A1/A2-Handlung werden nicht dokumentiert.",IF(F8="Kein passender BAM-Eintrag","Kein passender BAM-Eintrag der untersuchten Komponente; daher kein run-spezifischer BAM-Nachweis.",IF(F8="BAM-Eintrag vorhanden, Ausführungszeit nicht im Execution-Zeitraum","BAM-Eintrag vorhanden, die ExecutionTime gehört jedoch nicht zum betrachteten Experimentlauf; daher kein run-spezifischer Nachweis.","BAM-Eintrag vorhanden, aber der Referenzzeitraum des Runs ist in der bereitgestellten RunTabelle nicht verfügbar."))) -> Run-spezifischer BAM-Befund: Executable-Pfad und ExecutionTime ordnen die Zielkomponente direkt dem Lauf zu; Benutzerkontext liegt über die SID vor. Kommandozeile, Parent-Prozess und konkrete A1/A2-Handlung werden nicht dokumentiert.
A9: PS-A1-P2-R02 | B9: PowerShell | C9: A1 | D9: P2 | E9: R02 | F9: BAM-Treffer im Execution-Zeitraum | G9: S-1-5-21-4065717026-3980475814-3063633344-1001 | H9: \Device\HarddiskVolume3\Windows\System32\WindowsPowerShell\v1.0\powershell.exe | I9: 46255.579 | J9: 46255.662 | K9: 46255.662 | L9: 46255.662 | M9: =IF(F9="BAM-Treffer im Execution-Zeitraum",1,0) -> 1 | N9: =IF(M9=1,2,"-") -> 2 | O9: =IF(M9=1,2,"-") -> 2 | P9: =IF(M9=1,1,"-") -> 1 | Q9: =IF(M9=1,0,"-") -> 0 | R9: =IF(M9=1,0,"-") -> 0 | S9: =IF(M9=1,"Run-spezifischer BAM-Befund: Executable-Pfad und ExecutionTime ordnen die Zielkomponente direkt dem Lauf zu; Benutzerkontext liegt über die SID vor. Kommandozeile, Parent-Prozess und konkrete A1/A2-Handlung werden nicht dokumentiert.",IF(F9="Kein passender BAM-Eintrag","Kein passender BAM-Eintrag der untersuchten Komponente; daher kein run-spezifischer BAM-Nachweis.",IF(F9="BAM-Eintrag vorhanden, Ausführungszeit nicht im Execution-Zeitraum","BAM-Eintrag vorhanden, die ExecutionTime gehört jedoch nicht zum betrachteten Experimentlauf; daher kein run-spezifischer Nachweis.","BAM-Eintrag vorhanden, aber der Referenzzeitraum des Runs ist in der bereitgestellten RunTabelle nicht verfügbar."))) -> Run-spezifischer BAM-Befund: Executable-Pfad und ExecutionTime ordnen die Zielkomponente direkt dem Lauf zu; Benutzerkontext liegt über die SID vor. Kommandozeile, Parent-Prozess und konkrete A1/A2-Handlung werden nicht dokumentiert.
A10: PS-A1-P2-R03 | B10: PowerShell | C10: A1 | D10: P2 | E10: R03 | F10: BAM-Eintrag vorhanden, Ausführungszeit nicht im Execution-Zeitraum | G10: S-1-5-21-4065717026-3980475814-3063633344-1001 | H10: \Device\HarddiskVolume3\Windows\System32\WindowsPowerShell\v1.0\powershell.exe | I10: 46236.59 | J10: 46236.673 | K10: 46255.667 | L10: 46255.667 | M10: =IF(F10="BAM-Treffer im Execution-Zeitraum",1,0) -> 0 | N10: =IF(M10=1,2,"-") -> - | O10: =IF(M10=1,2,"-") -> - | P10: =IF(M10=1,1,"-") -> - | Q10: =IF(M10=1,0,"-") -> - | R10: =IF(M10=1,0,"-") -> - | S10: =IF(M10=1,"Run-spezifischer BAM-Befund: Executable-Pfad und ExecutionTime ordnen die Zielkomponente direkt dem Lauf zu; Benutzerkontext liegt über die SID vor. Kommandozeile, Parent-Prozess und konkrete A1/A2-Handlung werden nicht dokumentiert.",IF(F10="Kein passender BAM-Eintrag","Kein passender BAM-Eintrag der untersuchten Komponente; daher kein run-spezifischer BAM-Nachweis.",IF(F10="BAM-Eintrag vorhanden, Ausführungszeit nicht im Execution-Zeitraum","BAM-Eintrag vorhanden, die ExecutionTime gehört jedoch nicht zum betrachteten Experimentlauf; daher kein run-spezifischer Nachweis.","BAM-Eintrag vorhanden, aber der Referenzzeitraum des Runs ist in der bereitgestellten RunTabelle nicht verfügbar."))) -> BAM-Eintrag vorhanden, die ExecutionTime gehört jedoch nicht zum betrachteten Experimentlauf; daher kein run-spezifischer Nachweis.
A11: PS-A2-P0-R01 | B11: PowerShell | C11: A2 | D11: P0 | E11: R01 | F11: Kein passender BAM-Eintrag | K11: 46255.458 | L11: 46255.458 | M11: =IF(F11="BAM-Treffer im Execution-Zeitraum",1,0) -> 0 | N11: =IF(M11=1,2,"-") -> - | O11: =IF(M11=1,2,"-") -> - | P11: =IF(M11=1,1,"-") -> - | Q11: =IF(M11=1,0,"-") -> - | R11: =IF(M11=1,0,"-") -> - | S11: =IF(M11=1,"Run-spezifischer BAM-Befund: Executable-Pfad und ExecutionTime ordnen die Zielkomponente direkt dem Lauf zu; Benutzerkontext liegt über die SID vor. Kommandozeile, Parent-Prozess und konkrete A1/A2-Handlung werden nicht dokumentiert.",IF(F11="Kein passender BAM-Eintrag","Kein passender BAM-Eintrag der untersuchten Komponente; daher kein run-spezifischer BAM-Nachweis.",IF(F11="BAM-Eintrag vorhanden, Ausführungszeit nicht im Execution-Zeitraum","BAM-Eintrag vorhanden, die ExecutionTime gehört jedoch nicht zum betrachteten Experimentlauf; daher kein run-spezifischer Nachweis.","BAM-Eintrag vorhanden, aber der Referenzzeitraum des Runs ist in der bereitgestellten RunTabelle nicht verfügbar."))) -> Kein passender BAM-Eintrag der untersuchten Komponente; daher kein run-spezifischer BAM-Nachweis.
A12: PS-A2-P0-R02 | B12: PowerShell | C12: A2 | D12: P0 | E12: R02 | F12: Kein passender BAM-Eintrag | K12: 46255.464 | L12: 46255.464 | M12: =IF(F12="BAM-Treffer im Execution-Zeitraum",1,0) -> 0 | N12: =IF(M12=1,2,"-") -> - | O12: =IF(M12=1,2,"-") -> - | P12: =IF(M12=1,1,"-") -> - | Q12: =IF(M12=1,0,"-") -> - | R12: =IF(M12=1,0,"-") -> - | S12: =IF(M12=1,"Run-spezifischer BAM-Befund: Executable-Pfad und ExecutionTime ordnen die Zielkomponente direkt dem Lauf zu; Benutzerkontext liegt über die SID vor. Kommandozeile, Parent-Prozess und konkrete A1/A2-Handlung werden nicht dokumentiert.",IF(F12="Kein passender BAM-Eintrag","Kein passender BAM-Eintrag der untersuchten Komponente; daher kein run-spezifischer BAM-Nachweis.",IF(F12="BAM-Eintrag vorhanden, Ausführungszeit nicht im Execution-Zeitraum","BAM-Eintrag vorhanden, die ExecutionTime gehört jedoch nicht zum betrachteten Experimentlauf; daher kein run-spezifischer Nachweis.","BAM-Eintrag vorhanden, aber der Referenzzeitraum des Runs ist in der bereitgestellten RunTabelle nicht verfügbar."))) -> Kein passender BAM-Eintrag der untersuchten Komponente; daher kein run-spezifischer BAM-Nachweis.
A13: PS-A2-P0-R03 | B13: PowerShell | C13: A2 | D13: P0 | E13: R03 | F13: Kein passender BAM-Eintrag | K13: 46255.468 | L13: 46255.468 | M13: =IF(F13="BAM-Treffer im Execution-Zeitraum",1,0) -> 0 | N13: =IF(M13=1,2,"-") -> - | O13: =IF(M13=1,2,"-") -> - | P13: =IF(M13=1,1,"-") -> - | Q13: =IF(M13=1,0,"-") -> - | R13: =IF(M13=1,0,"-") -> - | S13: =IF(M13=1,"Run-spezifischer BAM-Befund: Executable-Pfad und ExecutionTime ordnen die Zielkomponente direkt dem Lauf zu; Benutzerkontext liegt über die SID vor. Kommandozeile, Parent-Prozess und konkrete A1/A2-Handlung werden nicht dokumentiert.",IF(F13="Kein passender BAM-Eintrag","Kein passender BAM-Eintrag der untersuchten Komponente; daher kein run-spezifischer BAM-Nachweis.",IF(F13="BAM-Eintrag vorhanden, Ausführungszeit nicht im Execution-Zeitraum","BAM-Eintrag vorhanden, die ExecutionTime gehört jedoch nicht zum betrachteten Experimentlauf; daher kein run-spezifischer Nachweis.","BAM-Eintrag vorhanden, aber der Referenzzeitraum des Runs ist in der bereitgestellten RunTabelle nicht verfügbar."))) -> Kein passender BAM-Eintrag der untersuchten Komponente; daher kein run-spezifischer BAM-Nachweis.
A14: PS-A2-P1-R01 | B14: PowerShell | C14: A2 | D14: P1 | E14: R01 | F14: Kein passender BAM-Eintrag | K14: 46255.558 | L14: 46255.558 | M14: =IF(F14="BAM-Treffer im Execution-Zeitraum",1,0) -> 0 | N14: =IF(M14=1,2,"-") -> - | O14: =IF(M14=1,2,"-") -> - | P14: =IF(M14=1,1,"-") -> - | Q14: =IF(M14=1,0,"-") -> - | R14: =IF(M14=1,0,"-") -> - | S14: =IF(M14=1,"Run-spezifischer BAM-Befund: Executable-Pfad und ExecutionTime ordnen die Zielkomponente direkt dem Lauf zu; Benutzerkontext liegt über die SID vor. Kommandozeile, Parent-Prozess und konkrete A1/A2-Handlung werden nicht dokumentiert.",IF(F14="Kein passender BAM-Eintrag","Kein passender BAM-Eintrag der untersuchten Komponente; daher kein run-spezifischer BAM-Nachweis.",IF(F14="BAM-Eintrag vorhanden, Ausführungszeit nicht im Execution-Zeitraum","BAM-Eintrag vorhanden, die ExecutionTime gehört jedoch nicht zum betrachteten Experimentlauf; daher kein run-spezifischer Nachweis.","BAM-Eintrag vorhanden, aber der Referenzzeitraum des Runs ist in der bereitgestellten RunTabelle nicht verfügbar."))) -> Kein passender BAM-Eintrag der untersuchten Komponente; daher kein run-spezifischer BAM-Nachweis.
A15: PS-A2-P1-R02 | B15: PowerShell | C15: A2 | D15: P1 | E15: R02 | F15: Kein passender BAM-Eintrag | K15: 46255.562 | L15: 46255.562 | M15: =IF(F15="BAM-Treffer im Execution-Zeitraum",1,0) -> 0 | N15: =IF(M15=1,2,"-") -> - | O15: =IF(M15=1,2,"-") -> - | P15: =IF(M15=1,1,"-") -> - | Q15: =IF(M15=1,0,"-") -> - | R15: =IF(M15=1,0,"-") -> - | S15: =IF(M15=1,"Run-spezifischer BAM-Befund: Executable-Pfad und ExecutionTime ordnen die Zielkomponente direkt dem Lauf zu; Benutzerkontext liegt über die SID vor. Kommandozeile, Parent-Prozess und konkrete A1/A2-Handlung werden nicht dokumentiert.",IF(F15="Kein passender BAM-Eintrag","Kein passender BAM-Eintrag der untersuchten Komponente; daher kein run-spezifischer BAM-Nachweis.",IF(F15="BAM-Eintrag vorhanden, Ausführungszeit nicht im Execution-Zeitraum","BAM-Eintrag vorhanden, die ExecutionTime gehört jedoch nicht zum betrachteten Experimentlauf; daher kein run-spezifischer Nachweis.","BAM-Eintrag vorhanden, aber der Referenzzeitraum des Runs ist in der bereitgestellten RunTabelle nicht verfügbar."))) -> Kein passender BAM-Eintrag der untersuchten Komponente; daher kein run-spezifischer BAM-Nachweis.
A16: PS-A2-P1-R03 | B16: PowerShell | C16: A2 | D16: P1 | E16: R03 | F16: Kein passender BAM-Eintrag | K16: 46255.565 | L16: 46255.565 | M16: =IF(F16="BAM-Treffer im Execution-Zeitraum",1,0) -> 0 | N16: =IF(M16=1,2,"-") -> - | O16: =IF(M16=1,2,"-") -> - | P16: =IF(M16=1,1,"-") -> - | Q16: =IF(M16=1,0,"-") -> - | R16: =IF(M16=1,0,"-") -> - | S16: =IF(M16=1,"Run-spezifischer BAM-Befund: Executable-Pfad und ExecutionTime ordnen die Zielkomponente direkt dem Lauf zu; Benutzerkontext liegt über die SID vor. Kommandozeile, Parent-Prozess und konkrete A1/A2-Handlung werden nicht dokumentiert.",IF(F16="Kein passender BAM-Eintrag","Kein passender BAM-Eintrag der untersuchten Komponente; daher kein run-spezifischer BAM-Nachweis.",IF(F16="BAM-Eintrag vorhanden, Ausführungszeit nicht im Execution-Zeitraum","BAM-Eintrag vorhanden, die ExecutionTime gehört jedoch nicht zum betrachteten Experimentlauf; daher kein run-spezifischer Nachweis.","BAM-Eintrag vorhanden, aber der Referenzzeitraum des Runs ist in der bereitgestellten RunTabelle nicht verfügbar."))) -> Kein passender BAM-Eintrag der untersuchten Komponente; daher kein run-spezifischer BAM-Nachweis.
A17: PS-A2-P2-R01 | B17: PowerShell | C17: A2 | D17: P2 | E17: R01 | F17: BAM-Treffer im Execution-Zeitraum | G17: S-1-5-21-4065717026-3980475814-3063633344-1001 | H17: \Device\HarddiskVolume3\Windows\System32\WindowsPowerShell\v1.0\powershell.exe | I17: 46255.59 | J17: 46255.673 | K17: 46255.673 | L17: 46255.673 | M17: =IF(F17="BAM-Treffer im Execution-Zeitraum",1,0) -> 1 | N17: =IF(M17=1,2,"-") -> 2 | O17: =IF(M17=1,2,"-") -> 2 | P17: =IF(M17=1,1,"-") -> 1 | Q17: =IF(M17=1,0,"-") -> 0 | R17: =IF(M17=1,0,"-") -> 0 | S17: =IF(M17=1,"Run-spezifischer BAM-Befund: Executable-Pfad und ExecutionTime ordnen die Zielkomponente direkt dem Lauf zu; Benutzerkontext liegt über die SID vor. Kommandozeile, Parent-Prozess und konkrete A1/A2-Handlung werden nicht dokumentiert.",IF(F17="Kein passender BAM-Eintrag","Kein passender BAM-Eintrag der untersuchten Komponente; daher kein run-spezifischer BAM-Nachweis.",IF(F17="BAM-Eintrag vorhanden, Ausführungszeit nicht im Execution-Zeitraum","BAM-Eintrag vorhanden, die ExecutionTime gehört jedoch nicht zum betrachteten Experimentlauf; daher kein run-spezifischer Nachweis.","BAM-Eintrag vorhanden, aber der Referenzzeitraum des Runs ist in der bereitgestellten RunTabelle nicht verfügbar."))) -> Run-spezifischer BAM-Befund: Executable-Pfad und ExecutionTime ordnen die Zielkomponente direkt dem Lauf zu; Benutzerkontext liegt über die SID vor. Kommandozeile, Parent-Prozess und konkrete A1/A2-Handlung werden nicht dokumentiert.
A18: PS-A2-P2-R02 | B18: PowerShell | C18: A2 | D18: P2 | E18: R02 | F18: BAM-Treffer im Execution-Zeitraum | G18: S-1-5-21-4065717026-3980475814-3063633344-1001 | H18: \Device\HarddiskVolume3\Windows\System32\WindowsPowerShell\v1.0\powershell.exe | I18: 46255.596 | J18: 46255.68 | K18: 46255.68 | L18: 46255.68 | M18: =IF(F18="BAM-Treffer im Execution-Zeitraum",1,0) -> 1 | N18: =IF(M18=1,2,"-") -> 2 | O18: =IF(M18=1,2,"-") -> 2 | P18: =IF(M18=1,1,"-") -> 1 | Q18: =IF(M18=1,0,"-") -> 0 | R18: =IF(M18=1,0,"-") -> 0 | S18: =IF(M18=1,"Run-spezifischer BAM-Befund: Executable-Pfad und ExecutionTime ordnen die Zielkomponente direkt dem Lauf zu; Benutzerkontext liegt über die SID vor. Kommandozeile, Parent-Prozess und konkrete A1/A2-Handlung werden nicht dokumentiert.",IF(F18="Kein passender BAM-Eintrag","Kein passender BAM-Eintrag der untersuchten Komponente; daher kein run-spezifischer BAM-Nachweis.",IF(F18="BAM-Eintrag vorhanden, Ausführungszeit nicht im Execution-Zeitraum","BAM-Eintrag vorhanden, die ExecutionTime gehört jedoch nicht zum betrachteten Experimentlauf; daher kein run-spezifischer Nachweis.","BAM-Eintrag vorhanden, aber der Referenzzeitraum des Runs ist in der bereitgestellten RunTabelle nicht verfügbar."))) -> Run-spezifischer BAM-Befund: Executable-Pfad und ExecutionTime ordnen die Zielkomponente direkt dem Lauf zu; Benutzerkontext liegt über die SID vor. Kommandozeile, Parent-Prozess und konkrete A1/A2-Handlung werden nicht dokumentiert.
A19: PS-A2-P2-R03 | B19: PowerShell | C19: A2 | D19: P2 | E19: R03 | F19: BAM-Treffer im Execution-Zeitraum | G19: S-1-5-21-4065717026-3980475814-3063633344-1001 | H19: \Device\HarddiskVolume3\Windows\System32\WindowsPowerShell\v1.0\powershell.exe | I19: 46255.604 | J19: 46255.687 | K19: 46255.687 | L19: 46255.687 | M19: =IF(F19="BAM-Treffer im Execution-Zeitraum",1,0) -> 1 | N19: =IF(M19=1,2,"-") -> 2 | O19: =IF(M19=1,2,"-") -> 2 | P19: =IF(M19=1,1,"-") -> 1 | Q19: =IF(M19=1,0,"-") -> 0 | R19: =IF(M19=1,0,"-") -> 0 | S19: =IF(M19=1,"Run-spezifischer BAM-Befund: Executable-Pfad und ExecutionTime ordnen die Zielkomponente direkt dem Lauf zu; Benutzerkontext liegt über die SID vor. Kommandozeile, Parent-Prozess und konkrete A1/A2-Handlung werden nicht dokumentiert.",IF(F19="Kein passender BAM-Eintrag","Kein passender BAM-Eintrag der untersuchten Komponente; daher kein run-spezifischer BAM-Nachweis.",IF(F19="BAM-Eintrag vorhanden, Ausführungszeit nicht im Execution-Zeitraum","BAM-Eintrag vorhanden, die ExecutionTime gehört jedoch nicht zum betrachteten Experimentlauf; daher kein run-spezifischer Nachweis.","BAM-Eintrag vorhanden, aber der Referenzzeitraum des Runs ist in der bereitgestellten RunTabelle nicht verfügbar."))) -> Run-spezifischer BAM-Befund: Executable-Pfad und ExecutionTime ordnen die Zielkomponente direkt dem Lauf zu; Benutzerkontext liegt über die SID vor. Kommandozeile, Parent-Prozess und konkrete A1/A2-Handlung werden nicht dokumentiert.
A20: MSHTA-A1-P0-R01 | B20: Mshta | C20: A1 | D20: P0 | E20: R01 | F20: BAM-Treffer im Execution-Zeitraum | G20: S-1-5-21-4065717026-3980475814-3063633344-1001 | H20: \Device\HarddiskVolume3\Windows\System32\mshta.exe | I20: 46255.39 | J20: 46255.473 | K20: 46255.473 | L20: 46255.473 | M20: =IF(F20="BAM-Treffer im Execution-Zeitraum",1,0) -> 1 | N20: =IF(M20=1,2,"-") -> 2 | O20: =IF(M20=1,2,"-") -> 2 | P20: =IF(M20=1,1,"-") -> 1 | Q20: =IF(M20=1,0,"-") -> 0 | R20: =IF(M20=1,0,"-") -> 0 | S20: =IF(M20=1,"Run-spezifischer BAM-Befund: Executable-Pfad und ExecutionTime ordnen die Zielkomponente direkt dem Lauf zu; Benutzerkontext liegt über die SID vor. Kommandozeile, Parent-Prozess und konkrete A1/A2-Handlung werden nicht dokumentiert.",IF(F20="Kein passender BAM-Eintrag","Kein passender BAM-Eintrag der untersuchten Komponente; daher kein run-spezifischer BAM-Nachweis.",IF(F20="BAM-Eintrag vorhanden, Ausführungszeit nicht im Execution-Zeitraum","BAM-Eintrag vorhanden, die ExecutionTime gehört jedoch nicht zum betrachteten Experimentlauf; daher kein run-spezifischer Nachweis.","BAM-Eintrag vorhanden, aber der Referenzzeitraum des Runs ist in der bereitgestellten RunTabelle nicht verfügbar."))) -> Run-spezifischer BAM-Befund: Executable-Pfad und ExecutionTime ordnen die Zielkomponente direkt dem Lauf zu; Benutzerkontext liegt über die SID vor. Kommandozeile, Parent-Prozess und konkrete A1/A2-Handlung werden nicht dokumentiert.
A21: MSHTA-A1-P0-R02 | B21: Mshta | C21: A1 | D21: P0 | E21: R02 | F21: BAM-Treffer im Execution-Zeitraum | G21: S-1-5-21-4065717026-3980475814-3063633344-1001 | H21: \Device\HarddiskVolume3\Windows\System32\mshta.exe | I21: 46255.394 | J21: 46255.478 | K21: 46255.478 | L21: 46255.478 | M21: =IF(F21="BAM-Treffer im Execution-Zeitraum",1,0) -> 1 | N21: =IF(M21=1,2,"-") -> 2 | O21: =IF(M21=1,2,"-") -> 2 | P21: =IF(M21=1,1,"-") -> 1 | Q21: =IF(M21=1,0,"-") -> 0 | R21: =IF(M21=1,0,"-") -> 0 | S21: =IF(M21=1,"Run-spezifischer BAM-Befund: Executable-Pfad und ExecutionTime ordnen die Zielkomponente direkt dem Lauf zu; Benutzerkontext liegt über die SID vor. Kommandozeile, Parent-Prozess und konkrete A1/A2-Handlung werden nicht dokumentiert.",IF(F21="Kein passender BAM-Eintrag","Kein passender BAM-Eintrag der untersuchten Komponente; daher kein run-spezifischer BAM-Nachweis.",IF(F21="BAM-Eintrag vorhanden, Ausführungszeit nicht im Execution-Zeitraum","BAM-Eintrag vorhanden, die ExecutionTime gehört jedoch nicht zum betrachteten Experimentlauf; daher kein run-spezifischer Nachweis.","BAM-Eintrag vorhanden, aber der Referenzzeitraum des Runs ist in der bereitgestellten RunTabelle nicht verfügbar."))) -> Run-spezifischer BAM-Befund: Executable-Pfad und ExecutionTime ordnen die Zielkomponente direkt dem Lauf zu; Benutzerkontext liegt über die SID vor. Kommandozeile, Parent-Prozess und konkrete A1/A2-Handlung werden nicht dokumentiert.
A22: MSHTA-A1-P0-R03 | B22: Mshta | C22: A1 | D22: P0 | E22: R03 | F22: BAM-Treffer im Execution-Zeitraum | G22: S-1-5-21-4065717026-3980475814-3063633344-1001 | H22: \Device\HarddiskVolume3\Windows\System32\mshta.exe | I22: 46255.402 | J22: 46255.485 | K22: 46255.485 | L22: 46255.485 | M22: =IF(F22="BAM-Treffer im Execution-Zeitraum",1,0) -> 1 | N22: =IF(M22=1,2,"-") -> 2 | O22: =IF(M22=1,2,"-") -> 2 | P22: =IF(M22=1,1,"-") -> 1 | Q22: =IF(M22=1,0,"-") -> 0 | R22: =IF(M22=1,0,"-") -> 0 | S22: =IF(M22=1,"Run-spezifischer BAM-Befund: Executable-Pfad und ExecutionTime ordnen die Zielkomponente direkt dem Lauf zu; Benutzerkontext liegt über die SID vor. Kommandozeile, Parent-Prozess und konkrete A1/A2-Handlung werden nicht dokumentiert.",IF(F22="Kein passender BAM-Eintrag","Kein passender BAM-Eintrag der untersuchten Komponente; daher kein run-spezifischer BAM-Nachweis.",IF(F22="BAM-Eintrag vorhanden, Ausführungszeit nicht im Execution-Zeitraum","BAM-Eintrag vorhanden, die ExecutionTime gehört jedoch nicht zum betrachteten Experimentlauf; daher kein run-spezifischer Nachweis.","BAM-Eintrag vorhanden, aber der Referenzzeitraum des Runs ist in der bereitgestellten RunTabelle nicht verfügbar."))) -> Run-spezifischer BAM-Befund: Executable-Pfad und ExecutionTime ordnen die Zielkomponente direkt dem Lauf zu; Benutzerkontext liegt über die SID vor. Kommandozeile, Parent-Prozess und konkrete A1/A2-Handlung werden nicht dokumentiert.
A23: MSHTA-A1-P1-R01 | B23: Mshta | C23: A1 | D23: P1 | E23: R01 | F23: BAM-Treffer im Execution-Zeitraum | G23: S-1-5-21-4065717026-3980475814-3063633344-1001 | H23: \Device\HarddiskVolume3\Windows\System32\mshta.exe | I23: 46255.485 | J23: 46255.568 | K23: 46255.568 | L23: 46255.568 | M23: =IF(F23="BAM-Treffer im Execution-Zeitraum",1,0) -> 1 | N23: =IF(M23=1,2,"-") -> 2 | O23: =IF(M23=1,2,"-") -> 2 | P23: =IF(M23=1,1,"-") -> 1 | Q23: =IF(M23=1,0,"-") -> 0 | R23: =IF(M23=1,0,"-") -> 0 | S23: =IF(M23=1,"Run-spezifischer BAM-Befund: Executable-Pfad und ExecutionTime ordnen die Zielkomponente direkt dem Lauf zu; Benutzerkontext liegt über die SID vor. Kommandozeile, Parent-Prozess und konkrete A1/A2-Handlung werden nicht dokumentiert.",IF(F23="Kein passender BAM-Eintrag","Kein passender BAM-Eintrag der untersuchten Komponente; daher kein run-spezifischer BAM-Nachweis.",IF(F23="BAM-Eintrag vorhanden, Ausführungszeit nicht im Execution-Zeitraum","BAM-Eintrag vorhanden, die ExecutionTime gehört jedoch nicht zum betrachteten Experimentlauf; daher kein run-spezifischer Nachweis.","BAM-Eintrag vorhanden, aber der Referenzzeitraum des Runs ist in der bereitgestellten RunTabelle nicht verfügbar."))) -> Run-spezifischer BAM-Befund: Executable-Pfad und ExecutionTime ordnen die Zielkomponente direkt dem Lauf zu; Benutzerkontext liegt über die SID vor. Kommandozeile, Parent-Prozess und konkrete A1/A2-Handlung werden nicht dokumentiert.
A24: MSHTA-A1-P1-R02 | B24: Mshta | C24: A1 | D24: P1 | E24: R02 | F24: BAM-Treffer im Execution-Zeitraum | G24: S-1-5-21-4065717026-3980475814-3063633344-1001 | H24: \Device\HarddiskVolume3\Windows\System32\mshta.exe | I24: 46255.488 | J24: 46255.572 | K24: 46255.572 | L24: 46255.572 | M24: =IF(F24="BAM-Treffer im Execution-Zeitraum",1,0) -> 1 | N24: =IF(M24=1,2,"-") -> 2 | O24: =IF(M24=1,2,"-") -> 2 | P24: =IF(M24=1,1,"-") -> 1 | Q24: =IF(M24=1,0,"-") -> 0 | R24: =IF(M24=1,0,"-") -> 0 | S24: =IF(M24=1,"Run-spezifischer BAM-Befund: Executable-Pfad und ExecutionTime ordnen die Zielkomponente direkt dem Lauf zu; Benutzerkontext liegt über die SID vor. Kommandozeile, Parent-Prozess und konkrete A1/A2-Handlung werden nicht dokumentiert.",IF(F24="Kein passender BAM-Eintrag","Kein passender BAM-Eintrag der untersuchten Komponente; daher kein run-spezifischer BAM-Nachweis.",IF(F24="BAM-Eintrag vorhanden, Ausführungszeit nicht im Execution-Zeitraum","BAM-Eintrag vorhanden, die ExecutionTime gehört jedoch nicht zum betrachteten Experimentlauf; daher kein run-spezifischer Nachweis.","BAM-Eintrag vorhanden, aber der Referenzzeitraum des Runs ist in der bereitgestellten RunTabelle nicht verfügbar."))) -> Run-spezifischer BAM-Befund: Executable-Pfad und ExecutionTime ordnen die Zielkomponente direkt dem Lauf zu; Benutzerkontext liegt über die SID vor. Kommandozeile, Parent-Prozess und konkrete A1/A2-Handlung werden nicht dokumentiert.
A25: MSHTA-A1-P1-R03 | B25: Mshta | C25: A1 | D25: P1 | E25: R03 | F25: BAM-Treffer im Execution-Zeitraum | G25: S-1-5-21-4065717026-3980475814-3063633344-1001 | H25: \Device\HarddiskVolume3\Windows\System32\mshta.exe | I25: 46255.491 | J25: 46255.575 | K25: 46255.575 | L25: 46255.575 | M25: =IF(F25="BAM-Treffer im Execution-Zeitraum",1,0) -> 1 | N25: =IF(M25=1,2,"-") -> 2 | O25: =IF(M25=1,2,"-") -> 2 | P25: =IF(M25=1,1,"-") -> 1 | Q25: =IF(M25=1,0,"-") -> 0 | R25: =IF(M25=1,0,"-") -> 0 | S25: =IF(M25=1,"Run-spezifischer BAM-Befund: Executable-Pfad und ExecutionTime ordnen die Zielkomponente direkt dem Lauf zu; Benutzerkontext liegt über die SID vor. Kommandozeile, Parent-Prozess und konkrete A1/A2-Handlung werden nicht dokumentiert.",IF(F25="Kein passender BAM-Eintrag","Kein passender BAM-Eintrag der untersuchten Komponente; daher kein run-spezifischer BAM-Nachweis.",IF(F25="BAM-Eintrag vorhanden, Ausführungszeit nicht im Execution-Zeitraum","BAM-Eintrag vorhanden, die ExecutionTime gehört jedoch nicht zum betrachteten Experimentlauf; daher kein run-spezifischer Nachweis.","BAM-Eintrag vorhanden, aber der Referenzzeitraum des Runs ist in der bereitgestellten RunTabelle nicht verfügbar."))) -> Run-spezifischer BAM-Befund: Executable-Pfad und ExecutionTime ordnen die Zielkomponente direkt dem Lauf zu; Benutzerkontext liegt über die SID vor. Kommandozeile, Parent-Prozess und konkrete A1/A2-Handlung werden nicht dokumentiert.
A26: MSHTA-A1-P2-R01 | B26: Mshta | C26: A1 | D26: P2 | E26: R01 | F26: BAM-Treffer im Execution-Zeitraum | G26: S-1-5-21-4065717026-3980475814-3063633344-1001 | H26: \Device\HarddiskVolume3\Windows\System32\mshta.exe | I26: 46255.611 | J26: 46255.694 | K26: 46255.694 | L26: 46255.694 | M26: =IF(F26="BAM-Treffer im Execution-Zeitraum",1,0) -> 1 | N26: =IF(M26=1,2,"-") -> 2 | O26: =IF(M26=1,2,"-") -> 2 | P26: =IF(M26=1,1,"-") -> 1 | Q26: =IF(M26=1,0,"-") -> 0 | R26: =IF(M26=1,0,"-") -> 0 | S26: =IF(M26=1,"Run-spezifischer BAM-Befund: Executable-Pfad und ExecutionTime ordnen die Zielkomponente direkt dem Lauf zu; Benutzerkontext liegt über die SID vor. Kommandozeile, Parent-Prozess und konkrete A1/A2-Handlung werden nicht dokumentiert.",IF(F26="Kein passender BAM-Eintrag","Kein passender BAM-Eintrag der untersuchten Komponente; daher kein run-spezifischer BAM-Nachweis.",IF(F26="BAM-Eintrag vorhanden, Ausführungszeit nicht im Execution-Zeitraum","BAM-Eintrag vorhanden, die ExecutionTime gehört jedoch nicht zum betrachteten Experimentlauf; daher kein run-spezifischer Nachweis.","BAM-Eintrag vorhanden, aber der Referenzzeitraum des Runs ist in der bereitgestellten RunTabelle nicht verfügbar."))) -> Run-spezifischer BAM-Befund: Executable-Pfad und ExecutionTime ordnen die Zielkomponente direkt dem Lauf zu; Benutzerkontext liegt über die SID vor. Kommandozeile, Parent-Prozess und konkrete A1/A2-Handlung werden nicht dokumentiert.
A27: MSHTA-A1-P2-R02 | B27: Mshta | C27: A1 | D27: P2 | E27: R02 | F27: BAM-Treffer im Execution-Zeitraum | G27: S-1-5-21-4065717026-3980475814-3063633344-1001 | H27: \Device\HarddiskVolume3\Windows\System32\mshta.exe | I27: 46255.623 | J27: 46255.706 | K27: 46255.706 | L27: 46255.706 | M27: =IF(F27="BAM-Treffer im Execution-Zeitraum",1,0) -> 1 | N27: =IF(M27=1,2,"-") -> 2 | O27: =IF(M27=1,2,"-") -> 2 | P27: =IF(M27=1,1,"-") -> 1 | Q27: =IF(M27=1,0,"-") -> 0 | R27: =IF(M27=1,0,"-") -> 0 | S27: =IF(M27=1,"Run-spezifischer BAM-Befund: Executable-Pfad und ExecutionTime ordnen die Zielkomponente direkt dem Lauf zu; Benutzerkontext liegt über die SID vor. Kommandozeile, Parent-Prozess und konkrete A1/A2-Handlung werden nicht dokumentiert.",IF(F27="Kein passender BAM-Eintrag","Kein passender BAM-Eintrag der untersuchten Komponente; daher kein run-spezifischer BAM-Nachweis.",IF(F27="BAM-Eintrag vorhanden, Ausführungszeit nicht im Execution-Zeitraum","BAM-Eintrag vorhanden, die ExecutionTime gehört jedoch nicht zum betrachteten Experimentlauf; daher kein run-spezifischer Nachweis.","BAM-Eintrag vorhanden, aber der Referenzzeitraum des Runs ist in der bereitgestellten RunTabelle nicht verfügbar."))) -> Run-spezifischer BAM-Befund: Executable-Pfad und ExecutionTime ordnen die Zielkomponente direkt dem Lauf zu; Benutzerkontext liegt über die SID vor. Kommandozeile, Parent-Prozess und konkrete A1/A2-Handlung werden nicht dokumentiert.
A28: MSHTA-A1-P2-R03 | B28: Mshta | C28: A1 | D28: P2 | E28: R03 | F28: BAM-Treffer im Execution-Zeitraum | G28: S-1-5-21-4065717026-3980475814-3063633344-1001 | H28: \Device\HarddiskVolume3\Windows\System32\mshta.exe | I28: 46255.644 | J28: 46255.728 | K28: 46255.728 | L28: 46255.728 | M28: =IF(F28="BAM-Treffer im Execution-Zeitraum",1,0) -> 1 | N28: =IF(M28=1,2,"-") -> 2 | O28: =IF(M28=1,2,"-") -> 2 | P28: =IF(M28=1,1,"-") -> 1 | Q28: =IF(M28=1,0,"-") -> 0 | R28: =IF(M28=1,0,"-") -> 0 | S28: =IF(M28=1,"Run-spezifischer BAM-Befund: Executable-Pfad und ExecutionTime ordnen die Zielkomponente direkt dem Lauf zu; Benutzerkontext liegt über die SID vor. Kommandozeile, Parent-Prozess und konkrete A1/A2-Handlung werden nicht dokumentiert.",IF(F28="Kein passender BAM-Eintrag","Kein passender BAM-Eintrag der untersuchten Komponente; daher kein run-spezifischer BAM-Nachweis.",IF(F28="BAM-Eintrag vorhanden, Ausführungszeit nicht im Execution-Zeitraum","BAM-Eintrag vorhanden, die ExecutionTime gehört jedoch nicht zum betrachteten Experimentlauf; daher kein run-spezifischer Nachweis.","BAM-Eintrag vorhanden, aber der Referenzzeitraum des Runs ist in der bereitgestellten RunTabelle nicht verfügbar."))) -> Run-spezifischer BAM-Befund: Executable-Pfad und ExecutionTime ordnen die Zielkomponente direkt dem Lauf zu; Benutzerkontext liegt über die SID vor. Kommandozeile, Parent-Prozess und konkrete A1/A2-Handlung werden nicht dokumentiert.
... A37: MSHTA-A2-P2-R03 | B37: Mshta | C37: A2 | D37: P2 | E37: R03 | F37: BAM-Treffer im Execution-Zeitraum | G37: S-1-5-21-4065717026-3980475814-3063633344-1001 | H37: \Device\HarddiskVolume3\Windows\System32\mshta.exe | I37: 46255.661 | J37: 46255.744 | K37: 46255.744 | L37: 46255.744 | M37: =IF(F37="BAM-Treffer im Execution-Zeitraum",1,0) -> 1 | N37: =IF(M37=1,2,"-") -> 2 | O37: =IF(M37=1,2,"-") -> 2 | P37: =IF(M37=1,1,"-") -> 1 | Q37: =IF(M37=1,0,"-") -> 0 | R37: =IF(M37=1,0,"-") -> 0 | S37: =IF(M37=1,"Run-spezifischer BAM-Befund: Executable-Pfad und ExecutionTime ordnen die Zielkomponente direkt dem Lauf zu; Benutzerkontext liegt über die SID vor. Kommandozeile, Parent-Prozess und konkrete A1/A2-Handlung werden nicht dokumentiert.",IF(F37="Kein passender BAM-Eintrag","Kein passender BAM-Eintrag der untersuchten Komponente; daher kein run-spezifischer BAM-Nachweis.",IF(F37="BAM-Eintrag vorhanden, Ausführungszeit nicht im Execution-Zeitraum","BAM-Eintrag vorhanden, die ExecutionTime gehört jedoch nicht zum betrachteten Experimentlauf; daher kein run-spezifischer Nachweis.","BAM-Eintrag vorhanden, aber der Referenzzeitraum des Runs ist in der bereitgestellten RunTabelle nicht verfügbar."))) -> Run-spezifischer BAM-Befund: Executable-Pfad und ExecutionTime ordnen die Zielkomponente direkt dem Lauf zu; Benutzerkontext liegt über die SID vor. Kommandozeile, Parent-Prozess und konkrete A1/A2-Handlung werden nicht dokumentiert.
A38: REG-A1-P0-R01 | B38: Regsvr32 | C38: A1 | D38: P0 | E38: R01 | F38: Kein passender BAM-Eintrag | K38: 46255.502 | L38: 46255.502 | M38: =IF(F38="BAM-Treffer im Execution-Zeitraum",1,0) -> 0 | N38: =IF(M38=1,2,"-") -> - | O38: =IF(M38=1,2,"-") -> - | P38: =IF(M38=1,1,"-") -> - | Q38: =IF(M38=1,0,"-") -> - | R38: =IF(M38=1,0,"-") -> - | S38: =IF(M38=1,"Run-spezifischer BAM-Befund: Executable-Pfad und ExecutionTime ordnen die Zielkomponente direkt dem Lauf zu; Benutzerkontext liegt über die SID vor. Kommandozeile, Parent-Prozess und konkrete A1/A2-Handlung werden nicht dokumentiert.",IF(F38="Kein passender BAM-Eintrag","Kein passender BAM-Eintrag der untersuchten Komponente; daher kein run-spezifischer BAM-Nachweis.",IF(F38="BAM-Eintrag vorhanden, Ausführungszeit nicht im Execution-Zeitraum","BAM-Eintrag vorhanden, die ExecutionTime gehört jedoch nicht zum betrachteten Experimentlauf; daher kein run-spezifischer Nachweis.","BAM-Eintrag vorhanden, aber der Referenzzeitraum des Runs ist in der bereitgestellten RunTabelle nicht verfügbar."))) -> Kein passender BAM-Eintrag der untersuchten Komponente; daher kein run-spezifischer BAM-Nachweis.
A39: REG-A1-P0-R02 | B39: Regsvr32 | C39: A1 | D39: P0 | E39: R02 | F39: Kein passender BAM-Eintrag | K39: 46255.505 | L39: 46255.505 | M39: =IF(F39="BAM-Treffer im Execution-Zeitraum",1,0) -> 0 | N39: =IF(M39=1,2,"-") -> - | O39: =IF(M39=1,2,"-") -> - | P39: =IF(M39=1,1,"-") -> - | Q39: =IF(M39=1,0,"-") -> - | R39: =IF(M39=1,0,"-") -> - | S39: =IF(M39=1,"Run-spezifischer BAM-Befund: Executable-Pfad und ExecutionTime ordnen die Zielkomponente direkt dem Lauf zu; Benutzerkontext liegt über die SID vor. Kommandozeile, Parent-Prozess und konkrete A1/A2-Handlung werden nicht dokumentiert.",IF(F39="Kein passender BAM-Eintrag","Kein passender BAM-Eintrag der untersuchten Komponente; daher kein run-spezifischer BAM-Nachweis.",IF(F39="BAM-Eintrag vorhanden, Ausführungszeit nicht im Execution-Zeitraum","BAM-Eintrag vorhanden, die ExecutionTime gehört jedoch nicht zum betrachteten Experimentlauf; daher kein run-spezifischer Nachweis.","BAM-Eintrag vorhanden, aber der Referenzzeitraum des Runs ist in der bereitgestellten RunTabelle nicht verfügbar."))) -> Kein passender BAM-Eintrag der untersuchten Komponente; daher kein run-spezifischer BAM-Nachweis.
A40: REG-A1-P0-R03 | B40: Regsvr32 | C40: A1 | D40: P0 | E40: R03 | F40: Kein passender BAM-Eintrag | K40: 46255.508 | L40: 46255.508 | M40: =IF(F40="BAM-Treffer im Execution-Zeitraum",1,0) -> 0 | N40: =IF(M40=1,2,"-") -> - | O40: =IF(M40=1,2,"-") -> - | P40: =IF(M40=1,1,"-") -> - | Q40: =IF(M40=1,0,"-") -> - | R40: =IF(M40=1,0,"-") -> - | S40: =IF(M40=1,"Run-spezifischer BAM-Befund: Executable-Pfad und ExecutionTime ordnen die Zielkomponente direkt dem Lauf zu; Benutzerkontext liegt über die SID vor. Kommandozeile, Parent-Prozess und konkrete A1/A2-Handlung werden nicht dokumentiert.",IF(F40="Kein passender BAM-Eintrag","Kein passender BAM-Eintrag der untersuchten Komponente; daher kein run-spezifischer BAM-Nachweis.",IF(F40="BAM-Eintrag vorhanden, Ausführungszeit nicht im Execution-Zeitraum","BAM-Eintrag vorhanden, die ExecutionTime gehört jedoch nicht zum betrachteten Experimentlauf; daher kein run-spezifischer Nachweis.","BAM-Eintrag vorhanden, aber der Referenzzeitraum des Runs ist in der bereitgestellten RunTabelle nicht verfügbar."))) -> Kein passender BAM-Eintrag der untersuchten Komponente; daher kein run-spezifischer BAM-Nachweis.
A41: REG-A1-P1-R01 | B41: Regsvr32 | C41: A1 | D41: P1 | E41: R01 | F41: Kein passender BAM-Eintrag | K41: 46255.591 | L41: 46255.591 | M41: =IF(F41="BAM-Treffer im Execution-Zeitraum",1,0) -> 0 | N41: =IF(M41=1,2,"-") -> - | O41: =IF(M41=1,2,"-") -> - | P41: =IF(M41=1,1,"-") -> - | Q41: =IF(M41=1,0,"-") -> - | R41: =IF(M41=1,0,"-") -> - | S41: =IF(M41=1,"Run-spezifischer BAM-Befund: Executable-Pfad und ExecutionTime ordnen die Zielkomponente direkt dem Lauf zu; Benutzerkontext liegt über die SID vor. Kommandozeile, Parent-Prozess und konkrete A1/A2-Handlung werden nicht dokumentiert.",IF(F41="Kein passender BAM-Eintrag","Kein passender BAM-Eintrag der untersuchten Komponente; daher kein run-spezifischer BAM-Nachweis.",IF(F41="BAM-Eintrag vorhanden, Ausführungszeit nicht im Execution-Zeitraum","BAM-Eintrag vorhanden, die ExecutionTime gehört jedoch nicht zum betrachteten Experimentlauf; daher kein run-spezifischer Nachweis.","BAM-Eintrag vorhanden, aber der Referenzzeitraum des Runs ist in der bereitgestellten RunTabelle nicht verfügbar."))) -> Kein passender BAM-Eintrag der untersuchten Komponente; daher kein run-spezifischer BAM-Nachweis.
A42: REG-A1-P1-R02 | B42: Regsvr32 | C42: A1 | D42: P1 | E42: R02 | F42: Kein passender BAM-Eintrag | K42: 46255.595 | L42: 46255.595 | M42: =IF(F42="BAM-Treffer im Execution-Zeitraum",1,0) -> 0 | N42: =IF(M42=1,2,"-") -> - | O42: =IF(M42=1,2,"-") -> - | P42: =IF(M42=1,1,"-") -> - | Q42: =IF(M42=1,0,"-") -> - | R42: =IF(M42=1,0,"-") -> - | S42: =IF(M42=1,"Run-spezifischer BAM-Befund: Executable-Pfad und ExecutionTime ordnen die Zielkomponente direkt dem Lauf zu; Benutzerkontext liegt über die SID vor. Kommandozeile, Parent-Prozess und konkrete A1/A2-Handlung werden nicht dokumentiert.",IF(F42="Kein passender BAM-Eintrag","Kein passender BAM-Eintrag der untersuchten Komponente; daher kein run-spezifischer BAM-Nachweis.",IF(F42="BAM-Eintrag vorhanden, Ausführungszeit nicht im Execution-Zeitraum","BAM-Eintrag vorhanden, die ExecutionTime gehört jedoch nicht zum betrachteten Experimentlauf; daher kein run-spezifischer Nachweis.","BAM-Eintrag vorhanden, aber der Referenzzeitraum des Runs ist in der bereitgestellten RunTabelle nicht verfügbar."))) -> Kein passender BAM-Eintrag der untersuchten Komponente; daher kein run-spezifischer BAM-Nachweis.
A43: REG-A1-P1-R03 | B43: Regsvr32 | C43: A1 | D43: P1 | E43: R03 | F43: Kein passender BAM-Eintrag | K43: 46255.598 | L43: 46255.598 | M43: =IF(F43="BAM-Treffer im Execution-Zeitraum",1,0) -> 0 | N43: =IF(M43=1,2,"-") -> - | O43: =IF(M43=1,2,"-") -> - | P43: =IF(M43=1,1,"-") -> - | Q43: =IF(M43=1,0,"-") -> - | R43: =IF(M43=1,0,"-") -> - | S43: =IF(M43=1,"Run-spezifischer BAM-Befund: Executable-Pfad und ExecutionTime ordnen die Zielkomponente direkt dem Lauf zu; Benutzerkontext liegt über die SID vor. Kommandozeile, Parent-Prozess und konkrete A1/A2-Handlung werden nicht dokumentiert.",IF(F43="Kein passender BAM-Eintrag","Kein passender BAM-Eintrag der untersuchten Komponente; daher kein run-spezifischer BAM-Nachweis.",IF(F43="BAM-Eintrag vorhanden, Ausführungszeit nicht im Execution-Zeitraum","BAM-Eintrag vorhanden, die ExecutionTime gehört jedoch nicht zum betrachteten Experimentlauf; daher kein run-spezifischer Nachweis.","BAM-Eintrag vorhanden, aber der Referenzzeitraum des Runs ist in der bereitgestellten RunTabelle nicht verfügbar."))) -> Kein passender BAM-Eintrag der untersuchten Komponente; daher kein run-spezifischer BAM-Nachweis.
A44: REG-A1-P2-R01 | B44: Regsvr32 | C44: A1 | D44: P2 | E44: R01 | F44: Kein passender BAM-Eintrag | K44: 46255.75 | L44: 46255.75 | M44: =IF(F44="BAM-Treffer im Execution-Zeitraum",1,0) -> 0 | N44: =IF(M44=1,2,"-") -> - | O44: =IF(M44=1,2,"-") -> - | P44: =IF(M44=1,1,"-") -> - | Q44: =IF(M44=1,0,"-") -> - | R44: =IF(M44=1,0,"-") -> - | S44: =IF(M44=1,"Run-spezifischer BAM-Befund: Executable-Pfad und ExecutionTime ordnen die Zielkomponente direkt dem Lauf zu; Benutzerkontext liegt über die SID vor. Kommandozeile, Parent-Prozess und konkrete A1/A2-Handlung werden nicht dokumentiert.",IF(F44="Kein passender BAM-Eintrag","Kein passender BAM-Eintrag der untersuchten Komponente; daher kein run-spezifischer BAM-Nachweis.",IF(F44="BAM-Eintrag vorhanden, Ausführungszeit nicht im Execution-Zeitraum","BAM-Eintrag vorhanden, die ExecutionTime gehört jedoch nicht zum betrachteten Experimentlauf; daher kein run-spezifischer Nachweis.","BAM-Eintrag vorhanden, aber der Referenzzeitraum des Runs ist in der bereitgestellten RunTabelle nicht verfügbar."))) -> Kein passender BAM-Eintrag der untersuchten Komponente; daher kein run-spezifischer BAM-Nachweis.
A45: REG-A1-P2-R02 | B45: Regsvr32 | C45: A1 | D45: P2 | E45: R02 | F45: Kein passender BAM-Eintrag | K45: 46255.755 | L45: 46255.755 | M45: =IF(F45="BAM-Treffer im Execution-Zeitraum",1,0) -> 0 | N45: =IF(M45=1,2,"-") -> - | O45: =IF(M45=1,2,"-") -> - | P45: =IF(M45=1,1,"-") -> - | Q45: =IF(M45=1,0,"-") -> - | R45: =IF(M45=1,0,"-") -> - | S45: =IF(M45=1,"Run-spezifischer BAM-Befund: Executable-Pfad und ExecutionTime ordnen die Zielkomponente direkt dem Lauf zu; Benutzerkontext liegt über die SID vor. Kommandozeile, Parent-Prozess und konkrete A1/A2-Handlung werden nicht dokumentiert.",IF(F45="Kein passender BAM-Eintrag","Kein passender BAM-Eintrag der untersuchten Komponente; daher kein run-spezifischer BAM-Nachweis.",IF(F45="BAM-Eintrag vorhanden, Ausführungszeit nicht im Execution-Zeitraum","BAM-Eintrag vorhanden, die ExecutionTime gehört jedoch nicht zum betrachteten Experimentlauf; daher kein run-spezifischer Nachweis.","BAM-Eintrag vorhanden, aber der Referenzzeitraum des Runs ist in der bereitgestellten RunTabelle nicht verfügbar."))) -> Kein passender BAM-Eintrag der untersuchten Komponente; daher kein run-spezifischer BAM-Nachweis.
A46: REG-A1-P2-R03 | B46: Regsvr32 | C46: A1 | D46: P2 | E46: R03 | F46: Kein passender BAM-Eintrag | K46: 46255.759 | L46: 46255.759 | M46: =IF(F46="BAM-Treffer im Execution-Zeitraum",1,0) -> 0 | N46: =IF(M46=1,2,"-") -> - | O46: =IF(M46=1,2,"-") -> - | P46: =IF(M46=1,1,"-") -> - | Q46: =IF(M46=1,0,"-") -> - | R46: =IF(M46=1,0,"-") -> - | S46: =IF(M46=1,"Run-spezifischer BAM-Befund: Executable-Pfad und ExecutionTime ordnen die Zielkomponente direkt dem Lauf zu; Benutzerkontext liegt über die SID vor. Kommandozeile, Parent-Prozess und konkrete A1/A2-Handlung werden nicht dokumentiert.",IF(F46="Kein passender BAM-Eintrag","Kein passender BAM-Eintrag der untersuchten Komponente; daher kein run-spezifischer BAM-Nachweis.",IF(F46="BAM-Eintrag vorhanden, Ausführungszeit nicht im Execution-Zeitraum","BAM-Eintrag vorhanden, die ExecutionTime gehört jedoch nicht zum betrachteten Experimentlauf; daher kein run-spezifischer Nachweis.","BAM-Eintrag vorhanden, aber der Referenzzeitraum des Runs ist in der bereitgestellten RunTabelle nicht verfügbar."))) -> Kein passender BAM-Eintrag der untersuchten Komponente; daher kein run-spezifischer BAM-Nachweis.
