Workbook

Sheet Rohdaten pro Run
A1: RunID | B1: Komponente | C1: Aktionsklasse | D1: LoggingProfil | E1: Wiederholung | F1: Prefetch-Status | G1: PrefetchDatei | H1: ExecutableName | I1: LastRun (UTC) | J1: LastRun lokal (+02:00) | K1: FilesLoaded | L1: Directories | M1: ParsingError | N1: SourcePF
A2: PS-A1-P0-R01 | B2: PowerShell | C2: A1 | D2: P0 | E2: R01 | F2: Prefetch-Treffer im Execution-Zeitraum | G2: POWERSHELL.EXE-CA1AE517.pf | H2: POWERSHELL.EXE | I2: 21.08.2026 08:29:08 | J2: 21.08.2026 10:29:08 | K2: \VOLUME{01dd20558af6da83-d08afee5}\WINDOWS\MICROSOFT.NET\ASSEMBLY\GAC_MSIL\MICROSOFT.POWERSHELL.CONSOLEHOST\V4.0_3.0.0.0__31BF3856AD364E35\MICROSOFT.POWERSHELL.CONSOLEHOST.DLL, \VOLUME{01dd20558af6da83-d08afee5}\PROGRAM FILES\WINDOWSPOWERSHELL\MODULES\PSREADLINE\2.0.0\MICROSOFT.POWERSHELL.PSREADLINE.DLL, \VOLUME{01dd20558af6da83-d08afee5}\PROGRAM FILES\WINDOWS DEFENDER\MSMPLICS.DLL, \VOLUME{01dd20558af6da83-d08afee5}\WINDOWS\SYSTEM32\NTDLL.DLL, \VOLUME{01dd20558af6da83-d08afee5}\WINDOWS\SYSTEM32\C_1252.NLS, \VOLUME{01dd20558af6da83-d08afee5}\WINDOWS\SYSTEM32\C_437.NLS, \VOLUME{01dd20558af6da83-d08afee5}\WINDOWS\SYSTEM32\L_INTL.NLS, \VOLUME{01dd20558af6da83-d08afee5}\WINDOWS\SYSTEM32\WINDOWSPOWERSHELL\V1.0\POWERSHELL.EXE, \VOLUME{01dd20558af6da83-d08afee5}\WINDOWS\SYSTEM32\KERNEL32.DLL, \VOLUME{01dd20558af6da83-d08afee5}\WINDOWS\SYSTEM32\KERNELBASE.DLL, \VOLUME{01dd20558af6da83-d08afee5}\WINDOWS\SYSTEM32\LOCALE.NLS, \VOLUME{01dd20558af6da83-d08afee5}\WINDOWS\SYSTEM32\MSVCRT.DLL, \VOLUME{01dd20558af6da83-d08afee5}\WINDOWS\SYSTEM32\OLEAUT32.DLL, \VOLUME{01dd20558af6da83-d08afee5}\WINDOWS\SYSTEM32\MSVCP_WIN.DLL, \VOLUME{01dd20558af6da83-d08afee5}\WINDOWS\SYSTEM32\UCRTBASE.DLL, \VOLUME{01dd20558af6da83-d08afee5}\WINDOWS\SYSTEM32\COMBASE.DLL, \VOLUME{01dd20558af6da83-d08afee5}\WINDOWS\SYSTEM32\RPCRT4.DLL, \VOLUME{01dd20558af6da83-d08afee5}\WINDOWS\SYSTEM32\ADVAPI32.DLL, \VOLUME{01dd20558af6da83-d08afee5}\WINDOWS\SYSTEM32\SECHOST.DLL, \VOLUME{01dd20558af6da83-d08afee5}\WINDOWS\SYSTEM32\OLE32.DLL, \VOLUME{01dd20558af6da83-d08afee5}\WINDOWS\SYSTEM32\GDI32.DLL, \VOLUME{01dd20558af6da83-d08afee5}\WINDOWS\SYSTEM32\WIN32U.DLL, \VOLUME{01dd20558af6da83-d08afee5}\WINDOWS\SYSTEM32\GDI32FULL.DLL, \VOLUME{01dd20558af6da83-d08afee5}\WINDOWS\SYSTEM32\USER32.DLL, \VOLUME{01dd20558af6da83-d08afee5}\WINDOWS\SYSTEM32\MSCOREE.DLL, \VOLUME{01dd20558af6da83-d08afee5}\WINDOWS\SYSTEM32\ATL.DLL, \VOLUME{01dd20558af6da83-d08afee5}\WINDOWS\SYSTEM32\IMM32.DLL, \VOLUME{01dd20558af6da83-d08afee5}\WINDOWS\SYSTEM32\WINDOWSPOWERSHELL\V1.0\EN-US\POWERSHELL.EXE.MUI, \VOLUME{01dd20558af6da83-d08afee5}\WINDOWS\GLOBALIZATION\SORTING\SORTDEFAULT.NLS, \VOLUME{01dd20558af6da83-d08afee5}\WINDOWS\MICROSOFT.NET\FRAMEWORK64\V4.0.30319\MSCOREEI.DLL, \VOLUME{01dd20558af6da83-d08afee5}\WINDOWS\SYSTEM32\SHLWAPI.DLL, \VOLUME{01dd20558af6da83-d08afee5}\WINDOWS\SYSTEM32\WINDOWSPOWERSHELL\V1.0\POWERSHELL.EXE.CONFIG, \VOLUME{01dd20558af6da83-d08afee5}\WINDOWS\SYSTEM32\KERNEL.APPCORE.DLL, \VOLUME{01dd20558af6da83-d08afee5}\WINDOWS\SYSTEM32\VERSION.DLL, \VOLUME{01dd20558af6da83-d08afee5}\WINDOWS\MICROSOFT.NET\FRAMEWORK64\V4.0.30319\CLR.DLL, \VOLUME{01dd20558af6da83-d08afee5}\WINDOWS\SYSTEM32\VCRUNTIME140_1_CLR0400.DLL, \VOLUME{01dd20558af6da83-d08afee5}\WINDOWS\SYSTEM32\VCRUNTIME140_CLR0400.DLL, \VOLUME{01dd20558af6da83-d08afee5}\WINDOWS\SYSTEM32\UCRTBASE_CLR0400.DLL, \VOLUME{01dd20558af6da83-d08afee5}\WINDOWS\MICROSOFT.NET\FRAMEWORK64\V4.0.30319\CONFIG\MACHINE.CONFIG, \VOLUME{01dd20558af6da83-d08afee5}\WINDOWS\ASSEMBLY\NATIVEIMAGES_V4.0.30319_64\MSCORLIB\3452D280CF55AE309A9FFBE81EA33A15\MSCORLIB.NI.DLL.AUX, \VOLUME{01dd20558af6da83-d08afee5}\WINDOWS\ASSEMBLY\NATIVEIMAGES_V4.0.30319_64\MSCORLIB\3452D280CF55AE309A9FFBE81EA33A15\MSCORLIB.NI.DLL, \VOLUME{01dd20558af6da83-d08afee5}\WINDOWS\SYSTEM32\RPCSS.DLL, \VOLUME{01dd20558af6da83-d08afee5}\WINDOWS\SYSTEM32\BCRYPTPRIMITIVES.DLL, \VOLUME{01dd20558af6da83-d08afee5}\WINDOWS\ASSEMBLY\NATIVEIMAGES_V4.0.30319_64\MICROSOFT.PB378EC07#\96F748786DB96E4095B0A0402A3CFCAE\MICROSOFT.POWERSHELL.CONSOLEHOST.NI.DLL.AUX, \VOLUME{01dd20558af6da83-d08afee5}\WINDOWS\SYSTEM32\CRYPTSP.DLL, \VOLUME{01dd20558af6da83-d08afee5}\WINDOWS\SYSTEM32\RSAENH.DLL, \VOLUME{01dd20558af6da83-d08afee5}\WINDOWS\SYSTEM32\CRYPTBASE.DLL, \VOLUME{01dd20558af6da83-d08afee5}\WINDOWS\SYSTEM32\BCRYPT.DLL, \VOLUME{01dd20558af6da83-d08afee5}\WINDOWS\MICROSOFT.NET\FRAMEWORK64\V4.0.30319\CLRJIT.DLL, \VOLUME{01dd20558af6da83-d08afee5}\WINDOWS\ASSEMBLY\NATIVEIMAGES_V4.0.30319_64\SYSTEM.MANAA57FC8CC#\A5059CABEE51B63CA636D3C567A63E6E\SYSTEM.MANAGEMENT.AUTOMATION.NI.DLL.AUX, \VOLUME{01dd20558af6da83-d08afee5}\WINDOWS\MICROSOFT.NET\ASSEMBLY\GAC_MSIL\SYSTEM.MANAGEMENT.AUTOMATION\V4.0_3.0.0.0__31BF3856AD364E35\SYSTEM.MANAGEMENT.AUTOMATION.DLL, \VOLUME{01dd20558af6da83-d08afee5}\WINDOWS\ASSEMBLY\NATIVEIMAGES_V4.0.30319_64\SYSTEM\2962E4ADB6482EE6FBABCB465600F685\SYSTEM.NI.DLL.AUX, \VOLUME{01dd20558af6da83-d08afee5}\WINDOWS\ASSEMBLY\NATIVEIMAGES_V4.0.30319_64\SYSTEM\2962E4ADB6482EE6FBABCB465600F685\SYSTEM.NI.DLL, \VOLUME{01dd20558af6da83-d08afee5}\WINDOWS\ASSEMBLY\NATIVEIMAGES_V4.0.30319_64\SYSTEM.CORE\0F70710D98654B6EB0F31C3CA310325D\SYSTEM.CORE.NI.DLL.AUX, \VOLUME{01dd20558af6da83-d08afee5}\WINDOWS\ASSEMBLY\NATIVEIMAGES_V4.0.30319_64\SYSTEM.CORE\0F70710D98654B6EB0F31C3CA310325D\SYSTEM.CORE.NI.DLL, \VOLUME{01dd20558af6da83-d08afee5}\WINDOWS\SYSTEM32\CLBCATQ.DLL, \VOLUME{01dd20558af6da83-d08afee5}\WINDOWS\SYSTEM32\WINNLSRES.DLL, \VOLUME{01dd20558af6da83-d08afee5}\WINDOWS\SYSTEM32\EN-US\WINNLSRES.DLL.MUI, \VOLUME{01dd20558af6da83-d08afee5}\WINDOWS\MICROSOFT.NET\FRAMEWORK64\V4.0.30319\MSCORRC.DLL, \VOLUME{01dd20558af6da83-d08afee5}\WINDOWS\SYSTEM32\PSAPI.DLL, \VOLUME{01dd20558af6da83-d08afee5}\WINDOWS\SYSTEM32\SHELL32.DLL, \VOLUME{01dd20558af6da83-d08afee5}\WINDOWS\SYSTEM32\WINDOWS.STORAGE.DLL, \VOLUME{01dd20558af6da83-d08afee5}\WINDOWS\SYSTEM32\SHCORE.DLL, \VOLUME{01dd20558af6da83-d08afee5}\WINDOWS\SYSTEM32\AMSI.DLL, \VOLUME{01dd20558af6da83-d08afee5}\WINDOWS\SYSTEM32\USERENV.DLL, \VOLUME{01dd20558af6da83-d08afee5}\WINDOWS\SYSTEM32\PROFAPI.DLL, \VOLUME{01dd20558af6da83-d08afee5}\PROGRAMDATA\MICROSOFT\WINDOWS DEFENDER\PLATFORM\4.18.26060.3008-0\MPOAV.DLL, \VOLUME{01dd20558af6da83-d08afee5}\WINDOWS\SYSTEM32\WINTRUST.DLL, \VOLUME{01dd20558af6da83-d08afee5}\WINDOWS\SYSTEM32\CRYPT32.DLL, \VOLUME{01dd20558af6da83-d08afee5}\WINDOWS\SYSTEM32\MSASN1.DLL, \VOLUME{01dd20558af6da83-d08afee5}\WINDOWS\SYSTEM32\WINDOWSPOWERSHELL\V1.0\MODULES\MICROSOFT.POWERSHELL.UTILITY\MICROSOFT.POWERSHELL.UTILITY.PSM1, \VOLUME{01dd20558af6da83-d08afee5}\WINDOWS\ASSEMBLY\NATIVEIMAGES_V4.0.30319_64\MICROSOFT.MF49F6405#\26CAF7C6CD61C21D731AD51C3C0B4692\MICROSOFT.MANAGEMENT.INFRASTRUCTURE.NI.DLL.AUX, \VOLUME{01dd20558af6da83-d08afee5}\WINDOWS\MICROSOFT.NET\ASSEMBLY\GAC_MSIL\MICROSOFT.MANAGEMENT.INFRASTRUCTURE\V4.0_1.0.0.0__31BF3856AD364E35\MICROSOFT.MANAGEMENT.INFRASTRUCTURE.DLL, \VOLUME{01dd20558af6da83-d08afee5}\WINDOWS\MICROSOFT.NET\ASSEMBLY\GAC_MSIL\SYSTEM.NUMERICS\V4.0_4.0.0.0__B77A5C561934E089\SYSTEM.NUMERICS.DLL, \VOLUME{01dd20558af6da83-d08afee5}\WINDOWS\ASSEMBLY\NATIVEIMAGES_V4.0.30319_64\SYSTEM.XML\C95D4C31D9E3487875DA6CC8F48489AE\SYSTEM.XML.NI.DLL.AUX, \VOLUME{01dd20558af6da83-d08afee5}\WINDOWS\ASSEMBLY\NATIVEIMAGES_V4.0.30319_64\SYSTEM.XML\C95D4C31D9E3487875DA6CC8F48489AE\SYSTEM.XML.NI.DLL, \VOLUME{01dd20558af6da83-d08afee5}\WINDOWS\SYSTEM32\GPAPI.DLL, \VOLUME{01dd20558af6da83-d08afee5}\WINDOWS\ASSEMBLY\NATIVEIMAGES_V4.0.30319_64\SYSTEM.DIRED13B18A9#\76A6F5B3696804F9492E9CF10ED3D90E\SYSTEM.DIRECTORYSERVICES.NI.DLL.AUX, \VOLUME{01dd20558af6da83-d08afee5}\WINDOWS\ASSEMBLY\NATIVEIMAGES_V4.0.30319_64\SYSTEM.DIRED13B18A9#\76A6F5B3696804F9492E9CF10ED3D90E\SYSTEM.DIRECTORYSERVICES.NI.DLL, \VOLUME{01dd20558af6da83-d08afee5}\WINDOWS\ASSEMBLY\NATIVEIMAGES_V4.0.30319_64\SYSTEM.MANAGEMENT\FD57ADD249214512518DFD4C91126290\SYSTEM.MANAGEMENT.NI.DLL.AUX, \VOLUME{01dd20558af6da83-d08afee5}\WINDOWS\ASSEMBLY\NATIVEIMAGES_V4.0.30319_64\SYSTEM.MANAGEMENT\FD57ADD249214512518DFD4C91126290\SYSTEM.MANAGEMENT.NI.DLL, \VOLUME{01dd20558af6da83-d08afee5}\WINDOWS\SYSTEM32\EN-US\CRYPT32.DLL.MUI, \VOLUME{01dd20558af6da83-d08afee5}\WINDOWS\ASSEMBLY\NATIVEIMAGES_V4.0.30319_64\SYSTEM.DATA\731DF61DCC7CAEA81C53AE5663E87341\SYSTEM.DATA.NI.DLL.AUX, \VOLUME{01dd20558af6da83-d08afee5}\WINDOWS\ASSEMBLY\NATIVEIMAGES_V4.0.30319_64\SYSTEM.DATA\731DF61DCC7CAEA81C53AE5663E87341\SYSTEM.DATA.NI.DLL, \VOLUME{01dd20558af6da83-d08afee5}\WINDOWS\SYSTEM32\WLDP.DLL, \VOLUME{01dd20558af6da83-d08afee5}\WINDOWS\SYSTEM32\CATROOT\{F750E6C3-38EE-11D1-85E5-00C04FC295EE}\MICROSOFT-WINDOWS-CLIENT-FEATURES-PACKAGE02~31BF3856AD364E35~AMD64~~10.0.26100.1591.CAT, \VOLUME{01dd20558af6da83-d08afee5}\WINDOWS\MICROSOFT.NET\ASSEMBLY\GAC_64\SYSTEM.DATA\V4.0_4.0.0.0__B77A5C561934E089\SYSTEM.DATA.DLL, \VOLUME{01dd20558af6da83-d08afee5}\WINDOWS\SYSTEM32\WS2_32.DLL, \VOLUME{01dd20558af6da83-d08afee5}\USERS\LABADMIN\APPDATA\LOCAL\TEMP\__PSSCRIPTPOLICYTEST_10NDB53E.KYT.PS1, \VOLUME{01dd20558af6da83-d08afee5}\USERS\LABADMIN\APPDATA\LOCAL\TEMP\__PSSCRIPTPOLICYTEST_A0HRKZU0.1GI.PSM1, \VOLUME{01dd20558af6da83-d08afee5}\WINDOWS\SYSTEM32\APPIDAPI.DLL, \VOLUME{01dd20558af6da83-d08afee5}\WINDOWS\SYSTEM32\SRPAPI.DLL, \VOLUME{01dd20558af6da83-d08afee5}\WINDOWS\SYSTEM32\UXTHEME.DLL, \VOLUME{01dd20558af6da83-d08afee5}\WINDOWS\ASSEMBLY\NATIVEIMAGES_V4.0.30319_64\SYSTEM.CONFIGURATION\EA379F2C8031866EF105C9BC09EBB71F\SYSTEM.CONFIGURATION.NI.DLL.AUX, \VOLUME{01dd20558af6da83-d08afee5}\WINDOWS\ASSEMBLY\NATIVEIMAGES_V4.0.30319_64\SYSTEM.CONFIGURATION\EA379F2C8031866EF105C9BC09EBB71F\SYSTEM.CONFIGURATION.NI.DLL, \VOLUME{01dd20558af6da83-d08afee5}\WINDOWS\SYSTEM32\TZRES.DLL, \VOLUME{01dd20558af6da83-d08afee5}\WINDOWS\SYSTEM32\EN-US\TZRES.DLL.MUI, \VOLUME{01dd20558af6da83-d08afee5}\WINDOWS\ASSEMBLY\NATIVEIMAGES_V4.0.30319_64\MICROSOFT.P6F792626#\381003111201B9E93BAA7D91C94CA1BB\MICROSOFT.POWERSHELL.SECURITY.NI.DLL.AUX, \VOLUME{01dd20558af6da83-d08afee5}\WINDOWS\MICROSOFT.NET\ASSEMBLY\GAC_MSIL\MICROSOFT.POWERSHELL.SECURITY\V4.0_3.0.0.0__31BF3856AD364E35\MICROSOFT.POWERSHELL.SECURITY.DLL, \VOLUME{01dd20558af6da83-d08afee5}\WINDOWS\ASSEMBLY\NATIVEIMAGES_V4.0.30319_64\SYSTEM.TRANSACTIONS\E11F704F862F782FBF1F8EAD40CD771A\SYSTEM.TRANSACTIONS.NI.DLL.AUX, \VOLUME{01dd20558af6da83-d08afee5}\WINDOWS\ASSEMBLY\NATIVEIMAGES_V4.0.30319_64\SYSTEM.TRANSACTIONS\E11F704F862F782FBF1F8EAD40CD771A\SYSTEM.TRANSACTIONS.NI.DLL, \VOLUME{01dd20558af6da83-d08afee5}\WINDOWS\MICROSOFT.NET\ASSEMBLY\GAC_64\SYSTEM.TRANSACTIONS\V4.0_4.0.0.0__B77A5C561934E089\SYSTEM.TRANSACTIONS.DLL, \VOLUME{01dd20558af6da83-d08afee5}\WINDOWS\SYSTEM32\SECUR32.DLL, \VOLUME{01dd20558af6da83-d08afee5}\WINDOWS\SYSTEM32\SSPICLI.DLL, \VOLUME{01dd20558af6da83-d08afee5}\PROGRAMDATA\MICROSOFT\WINDOWS DEFENDER\PLATFORM\4.18.26060.3008-0\MPCLIENT.DLL, \VOLUME{01dd20558af6da83-d08afee5}\PROGRAMDATA\MICROSOFT\WINDOWS DEFENDER\PLATFORM\4.18.26060.3008-0\MSMPLICS.DLL, \VOLUME{01dd20558af6da83-d08afee5}\LAB\TESTFILES\POWERSHELL\A1_POWERSHELL.PS1, \VOLUME{01dd20558af6da83-d08afee5}\USERS\LABADMIN\APPDATA\LOCAL\MICROSOFT\WINDOWS\POWERSHELL\MODULEANALYSISCACHE, \VOLUME{01dd20558af6da83-d08afee5}\WINDOWS\SYSTEM32\WINDOWSPOWERSHELL\V1.0\MODULES\MICROSOFT.POWERSHELL.MANAGEMENT\MICROSOFT.POWERSHELL.MANAGEMENT.PSD1, \VOLUME{01dd20558af6da83-d08afee5}\WINDOWS\ASSEMBLY\NATIVEIMAGES_V4.0.30319_64\MICROSOFT.PAE3498D9#\218ADA55D0662B02D4C67DF6B332E489\MICROSOFT.POWERSHELL.COMMANDS.MANAGEMENT.NI.DLL.AUX, \VOLUME{01dd20558af6da83-d08afee5}\WINDOWS\MICROSOFT.NET\ASSEMBLY\GAC_MSIL\MICROSOFT.POWERSHELL.COMMANDS.MANAGEMENT\V4.0_3.0.0.0__31BF3856AD364E35\MICROSOFT.POWERSHELL.COMMANDS.MANAGEMENT.DLL, \VOLUME{01dd20558af6da83-d08afee5}\WINDOWS\ASSEMBLY\NATIVEIMAGES_V4.0.30319_64\SYSTEM.CONFE64A9051#\4F44EE5C66D31D24EB1DBE2D52F3F677\SYSTEM.CONFIGURATION.INSTALL.NI.DLL.AUX, \VOLUME{01dd20558af6da83-d08afee5}\WINDOWS\ASSEMBLY\NATIVEIMAGES_V4.0.30319_64\SYSTEM.CONFE64A9051#\4F44EE5C66D31D24EB1DBE2D52F3F677\SYSTEM.CONFIGURATION.INSTALL.NI.DLL, \VOLUME{01dd20558af6da83-d08afee5}\WINDOWS\ASSEMBLY\NATIVEIMAGES_V4.0.30319_64\SYSTEM.SERV759BFB78#\E7253AFC5056A1BA48C382E8806D6CF7\SYSTEM.SERVICEPROCESS.NI.DLL.AUX, \VOLUME{01dd20558af6da83-d08afee5}\WINDOWS\ASSEMBLY\NATIVEIMAGES_V4.0.30319_64\SYSTEM.SERV759BFB78#\E7253AFC5056A1BA48C382E8806D6CF7\SYSTEM.SERVICEPROCESS.NI.DLL, \VOLUME{01dd20558af6da83-d08afee5}\WINDOWS\ASSEMBLY\NATIVEIMAGES_V4.0.30319_64\SYSTEM.WINDOWS.FORMS\DCD36ECC9F4807AE6091D89B21B70BD8\SYSTEM.WINDOWS.FORMS.NI.DLL.AUX, \VOLUME{01dd20558af6da83-d08afee5}\WINDOWS\ASSEMBLY\NATIVEIMAGES_V4.0.30319_64\SYSTEM.DRAWING\A7773EDDE31D2D5C70A2C9F3DD56E283\SYSTEM.DRAWING.NI.DLL.AUX, \VOLUME{01dd20558af6da83-d08afee5}\WINDOWS\ASSEMBLY\NATIVEIMAGES_V4.0.30319_64\SYSTEM.DRAWING\A7773EDDE31D2D5C70A2C9F3DD56E283\SYSTEM.DRAWING.NI.DLL, \VOLUME{01dd20558af6da83-d08afee5}\WINDOWS\ASSEMBLY\NATIVEIMAGES_V4.0.30319_64\SYSTEM.WINDOWS.FORMS\DCD36ECC9F4807AE6091D89B21B70BD8\SYSTEM.WINDOWS.FORMS.NI.DLL, \VOLUME{01dd20558af6da83-d08afee5}\LAB\OUTPUTS\A1\A1_POWERSHELL_RESULT.TXT, \VOLUME{01dd20558af6da83-d08afee5}\WINDOWS\SYSTEM32\WINDOWSPOWERSHELL\V1.0\MODULES\MICROSOFT.POWERSHELL.UTILITY\MICROSOFT.POWERSHELL.UTILITY.PSD1, \VOLUME{01dd20558af6da83-d08afee5}\WINDOWS\ASSEMBLY\NATIVEIMAGES_V4.0.30319_64\MICROSOFT.P521220EA#\DC85ECD3BAFF793073F0937951DE5157\MICROSOFT.POWERSHELL.COMMANDS.UTILITY.NI.DLL.AUX, \VOLUME{01dd20558af6da83-d08afee5}\WINDOWS\MICROSOFT.NET\ASSEMBLY\GAC_MSIL\MICROSOFT.POWERSHELL.COMMANDS.UTILITY\V4.0_3.0.0.0__31BF3856AD364E35\MICROSOFT.POWERSHELL.COMMANDS.UTILITY.DLL, \VOLUME{01dd20558af6da83-d08afee5}\WINDOWS\SYSTEM32\IPHLPAPI.DLL, \VOLUME{01dd20558af6da83-d08afee5}\WINDOWS\SYSTEM32\DNSAPI.DLL, \VOLUME{01dd20558af6da83-d08afee5}\WINDOWS\SYSTEM32\DSPARSE.DLL, \VOLUME{01dd20558af6da83-d08afee5}\WINDOWS\SYSTEM32\NSI.DLL, \VOLUME{01dd20558af6da83-d08afee5}\USERS\LABADMIN\APPDATA\LOCAL\MICROSOFT\WINDOWS\POWERSHELL\STARTUPPROFILEDATA-NONINTERACTIVE, \VOLUME{01dd20558af6da83-d08afee5}\WINDOWS\REGISTRATION\R000000000006.CLB, \VOLUME{01dd20558af6da83-d08afee5}\WINDOWS\SYSTEM32\APPRESOLVER.DLL, \VOLUME{01dd20558af6da83-d08afee5}\WINDOWS\SYSTEM32\MPR.DLL, \VOLUME{01dd20558af6da83-d08afee5}\USERS\LABADMIN\APPDATA\ROAMING\MICROSOFT\WINDOWS\START MENU\PROGRAMS\WINDOWS POWERSHELL\WINDOWS POWERSHELL.LNK, \VOLUME{01dd20558af6da83-d08afee5}\WINDOWS\SYSTEM32\PROPSYS.DLL, \VOLUME{01dd20558af6da83-d08afee5}\PROGRAMDATA\MICROSOFT\WINDOWS\CACHES\CVERSIONS.2.DB, \VOLUME{01dd20558af6da83-d08afee5}\PROGRAMDATA\MICROSOFT\WINDOWS\CACHES\{6AF0698E-D558-4F6E-9B3C-3716689AF493}.2.VER0X0000000000000002.DB, \VOLUME{01dd20558af6da83-d08afee5}\PROGRAMDATA\MICROSOFT\WINDOWS\CACHES\{DDF571F2-BE98-426D-8288-1A9A39C3FDA2}.2.VER0X0000000000000002.DB, \VOLUME{01dd20558af6da83-d08afee5}\WINDOWS\SYSTEM32\EN-US\PROPSYS.DLL.MUI, \VOLUME{01dd20558af6da83-d08afee5}\WINDOWS\SYSTEM32\LINKINFO.DLL, \VOLUME{01dd20558af6da83-d08afee5}\WINDOWS\SYSTEM32\CFGMGR32.DLL, \VOLUME{01dd20558af6da83-d08afee5}\USERS\LABADMIN\APPDATA\LOCAL\MICROSOFT\WINDOWS\CACHES\CVERSIONS.3.DB, \VOLUME{01dd20558af6da83-d08afee5}\USERS\LABADMIN\APPDATA\LOCAL\MICROSOFT\WINDOWS\CACHES\{3DA71D5A-20CC-432F-A115-DFE92379E91F}.3.VER0X000000000000000C.DB, \VOLUME{01dd20558af6da83-d08afee5}\WINDOWS\SYSTEM32\BCP47LANGS.DLL, \VOLUME{01dd20558af6da83-d08afee5}\USERS\LABADMIN\APPDATA\ROAMING\MICROSOFT\WINDOWS\RECENT\CUSTOMDESTINATIONS\590AEE7BDD69B59B.CUSTOMDESTINATIONS-MS, \VOLUME{01dd20558af6da83-d08afee5}\WINDOWS\SYSTEM32\URLMON.DLL, \VOLUME{01dd20558af6da83-d08afee5}\WINDOWS\SYSTEM32\IERTUTIL.DLL, \VOLUME{01dd20558af6da83-d08afee5}\WINDOWS\SYSTEM32\SRVCLI.DLL, \VOLUME{01dd20558af6da83-d08afee5}\WINDOWS\SYSTEM32\NETUTILS.DLL, \VOLUME{01dd20558af6da83-d08afee5}\WINDOWS\SYSTEM32\VIRTDISK.DLL, \VOLUME{01dd20558af6da83-d08afee5}\USERS\LABADMIN\APPDATA\LOCAL\MICROSOFT\WINDOWS\CACHES\CVERSIONS.1.DB, \VOLUME{01dd20558af6da83-d08afee5}\USERS\LABADMIN\APPDATA\LOCAL\MICROSOFT\WINDOWS\CACHES\{AFBF9F1A-8EE8-4C77-AF34-C647E37CA0D9}.1.VER0X0000000000000004.DB, \VOLUME{01dd20558af6da83-d08afee5}\USERS\DESKTOP.INI, \VOLUME{01dd20558af6da83-d08afee5}\USERS\LABADMIN\APPDATA\ROAMING\MICROSOFT\WINDOWS\START MENU\DESKTOP.INI, \VOLUME{01dd20558af6da83-d08afee5}\USERS\LABADMIN\APPDATA\ROAMING\MICROSOFT\WINDOWS\START MENU\PROGRAMS\DESKTOP.INI, \VOLUME{01dd20558af6da83-d08afee5}\USERS\LABADMIN\DESKTOP\DESKTOP.INI, \VOLUME{01dd20558af6da83-d08afee5}\USERS\LABADMIN\DOCUMENTS\DESKTOP.INI, \VOLUME{01dd20558af6da83-d08afee5}\USERS\LABADMIN\MUSIC\DESKTOP.INI, \VOLUME{01dd20558af6da83-d08afee5}\USERS\LABADMIN\PICTURES\DESKTOP.INI, \VOLUME{01dd20558af6da83-d08afee5}\USERS\LABADMIN\VIDEOS\DESKTOP.INI, \VOLUME{01dd20558af6da83-d08afee5}\USERS\LABADMIN\DOWNLOADS\DESKTOP.INI, \VOLUME{01dd20558af6da83-d08afee5}\USERS\LABADMIN\ONEDRIVE\DESKTOP.INI, \VOLUME{01dd20558af6da83-d08afee5}\USERS\LABADMIN\SEARCHES\DESKTOP.INI, \VOLUME{01dd20558af6da83-d08afee5}\USERS\LABADMIN\CONTACTS\DESKTOP.INI, \VOLUME{01dd20558af6da83-d08afee5}\WINDOWS\WIN.INI, \VOLUME{01dd20558af6da83-d08afee5}\USERS\LABADMIN\LINKS\DESKTOP.INI, \VOLUME{01dd20558af6da83-d08afee5}\USERS\LABADMIN\SAVED GAMES\DESKTOP.INI, \VOLUME{01dd20558af6da83-d08afee5}\WINDOWS\SYSTEM32\NTSHRUI.DLL, \VOLUME{01dd20558af6da83-d08afee5}\WINDOWS\SYSTEM32\CSCAPI.DLL, \VOLUME{01dd20558af6da83-d08afee5}\WINDOWS\SYSTEM32\POLICYMANAGER.DLL, \VOLUME{01dd20558af6da83-d08afee5}\USERS\LABADMIN\APPDATA\ROAMING\MICROSOFT\WINDOWS\RECENT\CUSTOMDESTINATIONS\U4X3YDE57MHVRPFIWAHO.TEMP, \VOLUME{01dd20558af6da83-d08afee5}\WINDOWS\SYSTEM32\NTMARTA.DLL, \VOLUME{01dd20558af6da83-d08afee5}\$MFT, \VOLUME{01dd20558af6da83-d08afee5}\USERS\LABADMIN\APPDATA\LOCAL\TEMP\__PSSCRIPTPOLICYTEST_QGF15B0L.EMJ.PS1, \VOLUME{01dd20558af6da83-d08afee5}\USERS\LABADMIN\APPDATA\LOCAL\TEMP\__PSSCRIPTPOLICYTEST_IHQJIG0D.CV0.PSM1, \VOLUME{01dd20558af6da83-d08afee5}\USERS\LABADMIN\APPDATA\LOCAL\MICROSOFT\WINDOWS\POWERSHELL\STARTUPPROFILEDATA-INTERACTIVE, \VOLUME{01dd20558af6da83-d08afee5}\PROGRAM FILES\WINDOWSPOWERSHELL\MODULES\PSREADLINE\2.0.0\PSREADLINE.PSD1, \VOLUME{01dd20558af6da83-d08afee5}\PROGRAM FILES\WINDOWSPOWERSHELL\MODULES\PSREADLINE\2.0.0\PSREADLINE.FORMAT.PS1XML, \VOLUME{01dd20558af6da83-d08afee5}\WINDOWS\SYSTEM32\EN-US\KERNELBASE.DLL.MUI, \VOLUME{01dd20558af6da83-d08afee5}\PROGRAM FILES\WINDOWSPOWERSHELL\MODULES\PSREADLINE\2.0.0\PSREADLINE.PSM1, \VOLUME{01dd20558af6da83-d08afee5}\USERS\LABADMIN\APPDATA\ROAMING\MICROSOFT\WINDOWS\POWERSHELL\PSREADLINE\CONSOLEHOST_HISTORY.TXT, \VOLUME{01dd20558af6da83-d08afee5}\USERS\LABADMIN\APPDATA\LOCAL\MICROSOFT\WINDOWS\CACHES\{3DA71D5A-20CC-432F-A115-DFE92379E91F}.3.VER0X000000000000000B.DB, \VOLUME{01dd20558af6da83-d08afee5}\USERS\LABADMIN\APPDATA\LOCAL\MICROSOFT\WINDOWS\CACHES\{AFBF9F1A-8EE8-4C77-AF34-C647E37CA0D9}.1.VER0X0000000000000003.DB, \VOLUME{01dd20558af6da83-d08afee5}\USERS\LABADMIN\APPDATA\ROAMING\MICROSOFT\WINDOWS\RECENT\CUSTOMDESTINATIONS\R983UAT3MXJ4KOY0VBNF.TEMP, \VOLUME{01dd20558af6da83-d08afee5}\USERS\LABADMIN\APPDATA\LOCAL\TEMP\__PSSCRIPTPOLICYTEST_P1ULCHWR.ABI.PS1, \VOLUME{01dd20558af6da83-d08afee5}\USERS\LABADMIN\APPDATA\LOCAL\TEMP\__PSSCRIPTPOLICYTEST_ML35RANT.L3V.PSM1, \VOLUME{01dd20558af6da83-d08afee5}\USERS\LABADMIN\APPDATA\ROAMING\MICROSOFT\WINDOWS\RECENT\CUSTOMDESTINATIONS\RW1UR4OMUAF7MJKRQO8M.TEMP, \VOLUME{01dd20558af6da83-d08afee5}\USERS\LABADMIN\APPDATA\LOCAL\TEMP\__PSSCRIPTPOLICYTEST_JEZYHODO.3HD.PS1, \VOLUME{01dd20558af6da83-d08afee5}\USERS\LABADMIN\APPDATA\LOCAL\TEMP\__PSSCRIPTPOLICYTEST_XOETGUB0.TJ2.PSM1, \VOLUME{01dd20558af6da83-d08afee5}\WINDOWS\SYSTEM32\MSWSOCK.DLL, \VOLUME{01dd20558af6da83-d08afee5}\WINDOWS\SYSTEM32\NAPINSP.DLL, \VOLUME{01dd20558af6da83-d08afee5}\WINDOWS\SYSTEM32\WINRNR.DLL, \VOLUME{01dd20558af6da83-d08afee5}\WINDOWS\SYSTEM32\NLANSP_C.DLL, \VOLUME{01dd20558af6da83-d08afee5}\WINDOWS\SYSTEM32\WSHBTH.DLL, \VOLUME{01dd20558af6da83-d08afee5}\WINDOWS\SYSTEM32\RASADHLP.DLL, \VOLUME{01dd20558af6da83-d08afee5}\WINDOWS\SYSTEM32\FWPUCLNT.DLL, \VOLUME{01dd20558af6da83-d08afee5}\WINDOWS\SYSTEM32\WBEM\WMIUTILS.DLL, \VOLUME{01dd20558af6da83-d08afee5}\WINDOWS\SYSTEM32\WBEMCOMN.DLL, \VOLUME{01dd20558af6da83-d08afee5}\WINDOWS\SYSTEM32\WBEM\WBEMPROX.DLL, \VOLUME{01dd20558af6da83-d08afee5}\WINDOWS\MICROSOFT.NET\FRAMEWORK64\V4.0.30319\WMINET_UTILS.DLL, \VOLUME{01dd20558af6da83-d08afee5}\WINDOWS\SYSTEM32\WBEM\WBEMSVC.DLL, \VOLUME{01dd20558af6da83-d08afee5}\WINDOWS\SYSTEM32\WBEM\FASTPROX.DLL, \VOLUME{01dd20558af6da83-d08afee5}\USERS\LABADMIN\APPDATA\LOCAL\MICROSOFT\WINDOWS\CACHES\{3DA71D5A-20CC-432F-A115-DFE92379E91F}.3.VER0X0000000000000009.DB, \VOLUME{01dd20558af6da83-d08afee5}\USERS\LABADMIN\APPDATA\ROAMING\MICROSOFT\WINDOWS\RECENT\CUSTOMDESTINATIONS\FCQY3B88QKL7R1P8VBBY.TEMP, \VOLUME{01dd20558af6da83-d08afee5}\PROGRAM FILES\WINDOWS DEFENDER\MPOAV.DLL, \VOLUME{01dd20558af6da83-d08afee5}\WINDOWS\SERVICING\PACKAGES\MICROSOFT-WINDOWS-CLIENT-FEATURES-PACKAGE02~31BF3856AD364E35~AMD64~~10.0.26100.1591.CAT, \VOLUME{01dd20558af6da83-d08afee5}\USERS\LABADMIN\APPDATA\LOCAL\TEMP\__PSSCRIPTPOLICYTEST_GZPDWNBH.0MN.PS1, \VOLUME{01dd20558af6da83-d08afee5}\USERS\LABADMIN\APPDATA\LOCAL\TEMP\__PSSCRIPTPOLICYTEST_0GWXY2J3.IR4.PSM1, \VOLUME{01dd20558af6da83-d08afee5}\PROGRAM FILES\WINDOWS DEFENDER\MPCLIENT.DLL, \VOLUME{01dd20558af6da83-d08afee5}\TOOLS\KAPE\KAPE.EXE, \VOLUME{01dd20558af6da83-d08afee5}\USERS\LABADMIN\APPDATA\ROAMING\MICROSOFT\WINDOWS\RECENT\CUSTOMDESTINATIONS\GXURK5IWCZJNPPAVKOME.TEMP, \VOLUME{01dd20558af6da83-d08afee5}\USERS\LABADMIN\APPDATA\LOCAL\TEMP\__PSSCRIPTPOLICYTEST_FC3YUGRA.V5M.PS1, \VOLUME{01dd20558af6da83-d08afee5}\USERS\LABADMIN\APPDATA\LOCAL\TEMP\__PSSCRIPTPOLICYTEST_5OEJRJMO.YZA.PSM1, \VOLUME{01dd20558af6da83-d08afee5}\WINDOWS\MICROSOFT.NET\ASSEMBLY\GAC_MSIL\MICROSOFT.CSHARP\V4.0_4.0.0.0__B03F5F7F11D50A3A\MICROSOFT.CSHARP.DLL, \VOLUME{01dd20558af6da83-d08afee5}\WINDOWS\MICROSOFT.NET\ASSEMBLY\GAC_MSIL\SYSTEM.DYNAMIC\V4.0_4.0.0.0__B03F5F7F11D50A3A\SYSTEM.DYNAMIC.DLL, \VOLUME{01dd20558af6da83-d08afee5}\PROGRAM FILES\WINDOWSPOWERSHELL\MODULES\MICROSOFT.POWERSHELL.OPERATION.VALIDATION\1.0.1\MICROSOFT.POWERSHELL.OPERATION.VALIDATION.PSD1, \VOLUME{01dd20558af6da83-d08afee5}\PROGRAM FILES\WINDOWSPOWERSHELL\MODULES\PACKAGEMANAGEMENT\1.0.0.1\PACKAGEMANAGEMENT.PSD1, \VOLUME{01dd20558af6da83-d08afee5}\PROGRAM FILES\WINDOWSPOWERSHELL\MODULES\PESTER\3.4.0\PESTER.PSD1, \VOLUME{01dd20558af6da83-d08afee5}\WINDOWS\SYSTEM32\CATROOT\{F750E6C3-38EE-11D1-85E5-00C04FC295EE}\MICROSOFT-WINDOWS-CLIENT-FEATURES-PACKAGE~31BF3856AD364E35~AMD64~~10.0.26100.8875.CAT, \VOLUME{01dd20558af6da83-d08afee5}\PROGRAM FILES\WINDOWSPOWERSHELL\MODULES\PESTER\3.4.0\PESTER.PSM1, \VOLUME{01dd20558af6da83-d08afee5}\PROGRAM FILES\WINDOWSPOWERSHELL\MODULES\POWERSHELLGET\1.0.0.1\POWERSHELLGET.PSD1, \VOLUME{01dd20558af6da83-d08afee5}\PROGRAM FILES\WINDOWSPOWERSHELL\MODULES\POWERSHELLGET\1.0.0.1\PSMODULE.PSM1, \VOLUME{01dd20558af6da83-d08afee5}\WINDOWS\SYSTEM32\WINDOWSPOWERSHELL\V1.0\MODULES\APPBACKGROUNDTASK\APPBACKGROUNDTASK.PSD1, \VOLUME{01dd20558af6da83-d08afee5}\WINDOWS\SYSTEM32\WINDOWSPOWERSHELL\V1.0\MODULES\APPLOCKER\APPLOCKER.PSD1, \VOLUME{01dd20558af6da83-d08afee5}\WINDOWS\SYSTEM32\CATROOT\{F750E6C3-38EE-11D1-85E5-00C04FC295EE}\MICROSOFT-WINDOWS-GROUPPOLICY-CLIENTTOOLS-WOW64-PACKAGE~31BF3856AD364E35~AMD64~~10.0.26100.8036.CAT, \VOLUME{01dd20558af6da83-d08afee5}\WINDOWS\SYSTEM32\WINDOWSPOWERSHELL\V1.0\MODULES\APPVCLIENT\APPVCLIENT.PSD1, \VOLUME{01dd20558af6da83-d08afee5}\WINDOWS\SYSTEM32\CATROOT\{F750E6C3-38EE-11D1-85E5-00C04FC295EE}\MICROSOFT-WINDOWS-APPMANAGEMENT-APPV-PACKAGE~31BF3856AD364E35~AMD64~~10.0.26100.8036.CAT, \VOLUME{01dd20558af6da83-d08afee5}\WINDOWS\ASSEMBLY\NATIVEIMAGES_V4.0.30319_64\MICROSOFT.M870D558A#\512F1AA771497F1C5A5CCCB99665A981\MICROSOFT.MANAGEMENT.INFRASTRUCTURE.NATIVE.NI.DLL.AUX, \VOLUME{01dd20558af6da83-d08afee5}\WINDOWS\MICROSOFT.NET\ASSEMBLY\GAC_64\MICROSOFT.MANAGEMENT.INFRASTRUCTURE.NATIVE\V4.0_1.0.0.0__31BF3856AD364E35\MICROSOFT.MANAGEMENT.INFRASTRUCTURE.NATIVE.DLL, \VOLUME{01dd20558af6da83-d08afee5}\USERS\LABADMIN\APPDATA\LOCAL\TEMP\__PSSCRIPTPOLICYTEST_DCSHQBNI.ROX.PS1, \VOLUME{01dd20558af6da83-d08afee5}\USERS\LABADMIN\APPDATA\LOCAL\TEMP\__PSSCRIPTPOLICYTEST_OQLIYVTL.MXT.PSM1, \VOLUME{01dd20558af6da83-d08afee5}\WINDOWS\SYSTEM32\WINDOWSPOWERSHELL\V1.0\MODULES\APPVCLIENT\MICROSOFT.APPV.APPVCLIENTPOWERSHELL.DLL, \VOLUME{01dd20558af6da83-d08afee5}\WINDOWS\MICROSOFT.NET\ASSEMBLY\GAC_64\MICROSOFT.APPV.APPVCLIENTCOMCONSUMER\V4.0_10.0.0.0__31BF3856AD364E35\MICROSOFT.APPV.APPVCLIENTCOMCONSUMER.DLL, \VOLUME{01dd20558af6da83-d08afee5}\WINDOWS\SYSTEM32\NORMALIZ.DLL, \VOLUME{01dd20558af6da83-d08afee5}\WINDOWS\SYSTEM32\WININET.DLL, \VOLUME{01dd20558af6da83-d08afee5}\WINDOWS\SYSTEM32\WINDOWSPOWERSHELL\V1.0\MODULES\APPX\APPX.PSD1, \VOLUME{01dd20558af6da83-d08afee5}\WINDOWS\SYSTEM32\CATROOT\{F750E6C3-38EE-11D1-85E5-00C04FC295EE}\MICROSOFT-WINDOWS-CLIENT-DESKTOP-REQUIRED-WOW64-PACKAGE0012~31BF3856AD364E35~AMD64~~10.0.26100.8875.CAT, \VOLUME{01dd20558af6da83-d08afee5}\WINDOWS\SYSTEM32\WINDOWSPOWERSHELL\V1.0\MODULES\APPX\EN-US\APPX.PSD1, \VOLUME{01dd20558af6da83-d08afee5}\WINDOWS\SYSTEM32\CATROOT\{F750E6C3-38EE-11D1-85E5-00C04FC295EE}\MICROSOFT-WINDOWS-CLIENT-DESKTOP-REQUIRED-PACKAGE0114~31BF3856AD364E35~AMD64~EN-US~10.0.26100.8875.CAT, \VOLUME{01dd20558af6da83-d08afee5}\WINDOWS\MICROSOFT.NET\ASSEMBLY\GAC_MSIL\MICROSOFT.WINDOWS.APPX.PACKAGEMANAGER.COMMANDS\V4.0_10.0.0.0__31BF3856AD364E35\MICROSOFT.WINDOWS.APPX.PACKAGEMANAGER.COMMANDS.DLL, \VOLUME{01dd20558af6da83-d08afee5}\WINDOWS\SYSTEM32\WINDOWS.APPLICATIONMODEL.DLL, \VOLUME{01dd20558af6da83-d08afee5}\WINDOWS\SYSTEM32\WINTYPES.DLL, \VOLUME{01dd20558af6da83-d08afee5}\WINDOWS\SYSTEM32\WINMETADATA\WINDOWS.MANAGEMENT.WINMD, \VOLUME{01dd20558af6da83-d08afee5}\WINDOWS\SYSTEM32\WINDOWSPOWERSHELL\V1.0\MODULES\ASSIGNEDACCESS\ASSIGNEDACCESS.PSD1, \VOLUME{01dd20558af6da83-d08afee5}\WINDOWS\SYSTEM32\WINDOWSPOWERSHELL\V1.0\MODULES\BITLOCKER\BITLOCKER.PSD1, \VOLUME{01dd20558af6da83-d08afee5}\WINDOWS\SYSTEM32\CATROOT\{F750E6C3-38EE-11D1-85E5-00C04FC295EE}\MICROSOFT-WINDOWS-SECURESTARTUP-SUBSYSTEM-WOW64-PACKAGE~31BF3856AD364E35~AMD64~~10.0.26100.7920.CAT, \VOLUME{01dd20558af6da83-d08afee5}\WINDOWS\SYSTEM32\WINDOWSPOWERSHELL\V1.0\MODULES\BITLOCKER\EN-US\BITLOCKER.PSD1, \VOLUME{01dd20558af6da83-d08afee5}\WINDOWS\SYSTEM32\CATROOT\{F750E6C3-38EE-11D1-85E5-00C04FC295EE}\MICROSOFT-WINDOWS-SECURESTARTUP-SUBSYSTEM-PACKAGE~31BF3856AD364E35~AMD64~EN-US~10.0.26100.8737.CAT, \VOLUME{01dd20558af6da83-d08afee5}\WINDOWS\SYSTEM32\WINDOWSPOWERSHELL\V1.0\MODULES\BITLOCKER\MICROSOFT.BITLOCKER.STRUCTURES.DLL, \VOLUME{01dd20558af6da83-d08afee5}\WINDOWS\SYSTEM32\WINDOWSPOWERSHELL\V1.0\MODULES\BITLOCKER\BITLOCKER.PSM1, \VOLUME{01dd20558af6da83-d08afee5}\WINDOWS\SYSTEM32\WINDOWSPOWERSHELL\V1.0\MODULES\BITSTRANSFER\BITSTRANSFER.PSD1, \VOLUME{01dd20558af6da83-d08afee5}\WINDOWS\SYSTEM32\WINDOWSPOWERSHELL\V1.0\MODULES\BRANCHCACHE\BRANCHCACHE.PSD1, \VOLUME{01dd20558af6da83-d08afee5}\WINDOWS\SYSTEM32\WINDOWSPOWERSHELL\V1.0\MODULES\CIMCMDLETS\CIMCMDLETS.PSD1, \VOLUME{01dd20558af6da83-d08afee5}\WINDOWS\SYSTEM32\WINDOWSPOWERSHELL\V1.0\MODULES\CONFIGCI\CONFIGCI.PSD1, \VOLUME{01dd20558af6da83-d08afee5}\WINDOWS\SYSTEM32\WINDOWSPOWERSHELL\V1.0\MODULES\DEFENDER\DEFENDER.PSD1, \VOLUME{01dd20558af6da83-d08afee5}\WINDOWS\SYSTEM32\CATROOT\{F750E6C3-38EE-11D1-85E5-00C04FC295EE}\MICROSOFT-WINDOWS-CLIENT-DESKTOP-REQUIRED-PACKAGE03~31BF3856AD364E35~AMD64~~10.0.26100.8875.CAT, \VOLUME{01dd20558af6da83-d08afee5}\WINDOWS\SYSTEM32\WINDOWSPOWERSHELL\V1.0\MODULES\DEFENDER\MSFT_MPCOMPUTERSTATUS.CDXML, \VOLUME{01dd20558af6da83-d08afee5}\WINDOWS\SYSTEM32\WINDOWSPOWERSHELL\V1.0\MODULES\DEFENDER\MSFT_MPPREFERENCE.CDXML, \VOLUME{01dd20558af6da83-d08afee5}\WINDOWS\SYSTEM32\WINDOWSPOWERSHELL\V1.0\MODULES\DEFENDER\MSFT_MPTHREAT.CDXML, \VOLUME{01dd20558af6da83-d08afee5}\WINDOWS\SYSTEM32\WINDOWSPOWERSHELL\V1.0\MODULES\DEFENDER\MSFT_MPTHREATCATALOG.CDXML, \VOLUME{01dd20558af6da83-d08afee5}\WINDOWS\SYSTEM32\WINDOWSPOWERSHELL\V1.0\MODULES\DEFENDER\MSFT_MPTHREATDETECTION.CDXML, \VOLUME{01dd20558af6da83-d08afee5}\WINDOWS\SYSTEM32\WINDOWSPOWERSHELL\V1.0\MODULES\DEFENDER\MSFT_MPSCAN.CDXML, \VOLUME{01dd20558af6da83-d08afee5}\WINDOWS\SYSTEM32\WINDOWSPOWERSHELL\V1.0\MODULES\DEFENDER\MSFT_MPSIGNATURE.CDXML, \VOLUME{01dd20558af6da83-d08afee5}\WINDOWS\SYSTEM32\WINDOWSPOWERSHELL\V1.0\MODULES\DEFENDER\MSFT_MPWDOSCAN.CDXML, \VOLUME{01dd20558af6da83-d08afee5}\WINDOWS\SYSTEM32\WINDOWSPOWERSHELL\V1.0\MODULES\DEFENDER\MSFT_MPROLLBACK.CDXML, \VOLUME{01dd20558af6da83-d08afee5}\WINDOWS\SYSTEM32\WINDOWSPOWERSHELL\V1.0\MODULES\DEFENDER\MSFT_MPBEHAVIORALNETWORKBLOCKINGRULES.CDXML, \VOLUME{01dd20558af6da83-d08afee5}\WINDOWS\SYSTEM32\WINDOWSPOWERSHELL\V1.0\MODULES\DEFENDERPERFORMANCE\DEFENDERPERFORMANCE.PSD1, \VOLUME{01dd20558af6da83-d08afee5}\WINDOWS\SYSTEM32\WINDOWSPOWERSHELL\V1.0\MODULES\DELIVERYOPTIMIZATION\DELIVERYOPTIMIZATION.PSD1, \VOLUME{01dd20558af6da83-d08afee5}\WINDOWS\SYSTEM32\WINDOWSPOWERSHELL\V1.0\MODULES\DIRECTACCESSCLIENTCOMPONENTS\DIRECTACCESSCLIENTCOMPONENTS.PSD1, \VOLUME{01dd20558af6da83-d08afee5}\WINDOWS\SYSTEM32\WINDOWSPOWERSHELL\V1.0\MODULES\DISM\DISM.PSD1, \VOLUME{01dd20558af6da83-d08afee5}\WINDOWS\SYSTEM32\WINDOWSPOWERSHELL\V1.0\MODULES\DNSCLIENT\DNSCLIENT.PSD1, \VOLUME{01dd20558af6da83-d08afee5}\WINDOWS\SYSTEM32\WINDOWSPOWERSHELL\V1.0\MODULES\EVENTTRACINGMANAGEMENT\EVENTTRACINGMANAGEMENT.PSD1, \VOLUME{01dd20558af6da83-d08afee5}\WINDOWS\SERVICING\PACKAGES\MICROSOFT-WINDOWS-CLIENT-FEATURES-WOW64-PACKAGE01~31BF3856AD364E35~AMD64~~10.0.26100.1742.CAT, \VOLUME{01dd20558af6da83-d08afee5}\WINDOWS\SYSTEM32\WINDOWSPOWERSHELL\V1.0\MODULES\EVENTTRACINGMANAGEMENT\MSFT_ETWTRACESESSION_V1.0.CDXML, \VOLUME{01dd20558af6da83-d08afee5}\WINDOWS\SYSTEM32\WINDOWSPOWERSHELL\V1.0\MODULES\EVENTTRACINGMANAGEMENT\MSFT_ETWTRACEPROVIDER_V1.0.CDXML, \VOLUME{01dd20558af6da83-d08afee5}\WINDOWS\SYSTEM32\WINDOWSPOWERSHELL\V1.0\MODULES\EVENTTRACINGMANAGEMENT\MSFT_AUTOLOGGERCONFIG_V1.0.CDXML, \VOLUME{01dd20558af6da83-d08afee5}\WINDOWS\SYSTEM32\WINDOWSPOWERSHELL\V1.0\MODULES\GET-NETVIEW\GET-NETVIEW.PSD1, \VOLUME{01dd20558af6da83-d08afee5}\WINDOWS\SYSTEM32\WINDOWSPOWERSHELL\V1.0\MODULES\INTERNATIONAL\INTERNATIONAL.PSD1, \VOLUME{01dd20558af6da83-d08afee5}\WINDOWS\SERVICING\PACKAGES\MICROSOFT-WINDOWS-CLIENT-DESKTOP-REQUIRED-PACKAGE0417~31BF3856AD364E35~AMD64~~10.0.26100.1742.CAT, \VOLUME{01dd20558af6da83-d08afee5}\WINDOWS\SYSTEM32\WINDOWSPOWERSHELL\V1.0\MODULES\ISCSI\ISCSI.PSD1, \VOLUME{01dd20558af6da83-d08afee5}\WINDOWS\SYSTEM32\WINDOWSPOWERSHELL\V1.0\MODULES\ISE\ISE.PSD1, \VOLUME{01dd20558af6da83-d08afee5}\WINDOWS\SYSTEM32\WINDOWSPOWERSHELL\V1.0\MODULES\KDS\KDS.PSD1, \VOLUME{01dd20558af6da83-d08afee5}\WINDOWS\SERVICING\PACKAGES\MICROSOFT-WINDOWS-CLIENT-FEATURES-PACKAGE03~31BF3856AD364E35~AMD64~~10.0.26100.1742.CAT, \VOLUME{01dd20558af6da83-d08afee5}\WINDOWS\ASSEMBLY\NATIVEIMAGES_V4.0.30319_64\MICROSOFT.KD58820A5#\001B8E35D03EDAF35B4B456F79405497\MICROSOFT.KEYDISTRIBUTIONSERVICE.CMDLETS.NI.DLL.AUX, \VOLUME{01dd20558af6da83-d08afee5}\WINDOWS\MICROSOFT.NET\ASSEMBLY\GAC_64\MICROSOFT.KEYDISTRIBUTIONSERVICE.CMDLETS\V4.0_10.0.0.0__31BF3856AD364E35\MICROSOFT.KEYDISTRIBUTIONSERVICE.CMDLETS.DLL, \VOLUME{01dd20558af6da83-d08afee5}\WINDOWS\SYSTEM32\WLDAP32.DLL, \VOLUME{01dd20558af6da83-d08afee5}\WINDOWS\SYSTEM32\KDSCLI.DLL, \VOLUME{01dd20558af6da83-d08afee5}\WINDOWS\SYSTEM32\WINDOWSPOWERSHELL\V1.0\MODULES\LANGUAGEPACKMANAGEMENT\LANGUAGEPACKMANAGEMENT.PSD1, \VOLUME{01dd20558af6da83-d08afee5}\WINDOWS\SYSTEM32\WINDOWSPOWERSHELL\V1.0\MODULES\LAPS\LAPS.PSD1, \VOLUME{01dd20558af6da83-d08afee5}\WINDOWS\SYSTEM32\WINDOWSPOWERSHELL\V1.0\MODULES\MICROSOFT.POWERSHELL.ARCHIVE\MICROSOFT.POWERSHELL.ARCHIVE.PSD1, \VOLUME{01dd20558af6da83-d08afee5}\WINDOWS\SYSTEM32\WINDOWSPOWERSHELL\V1.0\MODULES\MICROSOFT.POWERSHELL.DIAGNOSTICS\MICROSOFT.POWERSHELL.DIAGNOSTICS.PSD1, \VOLUME{01dd20558af6da83-d08afee5}\WINDOWS\SYSTEM32\WINDOWSPOWERSHELL\V1.0\MODULES\MICROSOFT.POWERSHELL.HOST\MICROSOFT.POWERSHELL.HOST.PSD1, \VOLUME{01dd20558af6da83-d08afee5}\WINDOWS\SYSTEM32\WINDOWSPOWERSHELL\V1.0\MODULES\MICROSOFT.POWERSHELL.LOCALACCOUNTS\1.0.0.0\MICROSOFT.POWERSHELL.LOCALACCOUNTS.PSD1, \VOLUME{01dd20558af6da83-d08afee5}\WINDOWS\SYSTEM32\WINDOWSPOWERSHELL\V1.0\MODULES\MICROSOFT.POWERSHELL.LOCALACCOUNTS\1.0.0.0\MICROSOFT.POWERSHELL.LOCALACCOUNTS.DLL, \VOLUME{01dd20558af6da83-d08afee5}\WINDOWS\SYSTEM32\WINDOWSPOWERSHELL\V1.0\MODULES\MICROSOFT.POWERSHELL.ODATAUTILS\MICROSOFT.POWERSHELL.ODATAUTILS.PSD1, \VOLUME{01dd20558af6da83-d08afee5}\WINDOWS\SYSTEM32\WINDOWSPOWERSHELL\V1.0\MODULES\MICROSOFT.POWERSHELL.SECURITY\MICROSOFT.POWERSHELL.SECURITY.PSD1, \VOLUME{01dd20558af6da83-d08afee5}\WINDOWS\SYSTEM32\WINDOWSPOWERSHELL\V1.0\MODULES\MICROSOFT.REFSDEDUP.COMMANDS\MICROSOFT.REFSDEDUP.COMMANDS.PSD1, \VOLUME{01dd20558af6da83-d08afee5}\WINDOWS\SYSTEM32\WINDOWSPOWERSHELL\V1.0\MODULES\MICROSOFT.WINDOWS.BCD.CMDLETS\MICROSOFT.WINDOWS.BCD.CMDLETS.PSD1, \VOLUME{01dd20558af6da83-d08afee5}\WINDOWS\SYSTEM32\WINDOWSPOWERSHELL\V1.0\MODULES\MICROSOFT.WSMAN.MANAGEMENT\MICROSOFT.WSMAN.MANAGEMENT.PSD1, \VOLUME{01dd20558af6da83-d08afee5}\WINDOWS\SYSTEM32\WINDOWSPOWERSHELL\V1.0\MODULES\MMAGENT\MMAGENT.PSD1, \VOLUME{01dd20558af6da83-d08afee5}\WINDOWS\SYSTEM32\WINDOWSPOWERSHELL\V1.0\MODULES\MSDTC\MSDTC.PSD1, \VOLUME{01dd20558af6da83-d08afee5}\WINDOWS\SERVICING\PACKAGES\MICROSOFT-WINDOWS-CLIENT-FEATURES-PACKAGE~31BF3856AD | L2: \VOLUME{01dd20558af6da83-d08afee5}\PROGRAM FILES, \VOLUME{01dd20558af6da83-d08afee5}\PROGRAM FILES\WINDOWS DEFENDER, \VOLUME{01dd20558af6da83-d08afee5}\PROGRAM FILES\WINDOWSPOWERSHELL, \VOLUME{01dd20558af6da83-d08afee5}\PROGRAM FILES\WINDOWSPOWERSHELL\MODULES, \VOLUME{01dd20558af6da83-d08afee5}\PROGRAM FILES\WINDOWSPOWERSHELL\MODULES\PESTER, \VOLUME{01dd20558af6da83-d08afee5}\PROGRAM FILES\WINDOWSPOWERSHELL\MODULES\PSREADLINE, \VOLUME{01dd20558af6da83-d08afee5}\PROGRAM FILES\WINDOWSPOWERSHELL\MODULES\PSREADLINE\2.0.0, \VOLUME{01dd20558af6da83-d08afee5}\PROGRAMDATA, \VOLUME{01dd20558af6da83-d08afee5}\PROGRAMDATA\MICROSOFT, \VOLUME{01dd20558af6da83-d08afee5}\PROGRAMDATA\MICROSOFT\WINDOWS, \VOLUME{01dd20558af6da83-d08afee5}\PROGRAMDATA\MICROSOFT\WINDOWS DEFENDER, \VOLUME{01dd20558af6da83-d08afee5}\PROGRAMDATA\MICROSOFT\WINDOWS DEFENDER\PLATFORM, \VOLUME{01dd20558af6da83-d08afee5}\PROGRAMDATA\MICROSOFT\WINDOWS DEFENDER\PLATFORM\4.18.26060.3008-0, \VOLUME{01dd20558af6da83-d08afee5}\PROGRAMDATA\MICROSOFT\WINDOWS\CACHES, \VOLUME{01dd20558af6da83-d08afee5}\USERS, \VOLUME{01dd20558af6da83-d08afee5}\USERS\LABADMIN, \VOLUME{01dd20558af6da83-d08afee5}\USERS\LABADMIN\APPDATA, \VOLUME{01dd20558af6da83-d08afee5}\USERS\LABADMIN\APPDATA\LOCAL, \VOLUME{01dd20558af6da83-d08afee5}\USERS\LABADMIN\APPDATA\LOCAL\MICROSOFT, \VOLUME{01dd20558af6da83-d08afee5}\USERS\LABADMIN\APPDATA\LOCAL\MICROSOFT\WINDOWS, \VOLUME{01dd20558af6da83-d08afee5}\USERS\LABADMIN\APPDATA\LOCAL\MICROSOFT\WINDOWS\CACHES, \VOLUME{01dd20558af6da83-d08afee5}\USERS\LABADMIN\APPDATA\LOCAL\MICROSOFT\WINDOWS\POWERSHELL, \VOLUME{01dd20558af6da83-d08afee5}\USERS\LABADMIN\APPDATA\ROAMING, \VOLUME{01dd20558af6da83-d08afee5}\USERS\LABADMIN\APPDATA\ROAMING\MICROSOFT, \VOLUME{01dd20558af6da83-d08afee5}\USERS\LABADMIN\APPDATA\ROAMING\MICROSOFT\WINDOWS, \VOLUME{01dd20558af6da83-d08afee5}\USERS\LABADMIN\APPDATA\ROAMING\MICROSOFT\WINDOWS\RECENT, \VOLUME{01dd20558af6da83-d08afee5}\USERS\LABADMIN\APPDATA\ROAMING\MICROSOFT\WINDOWS\RECENT\CUSTOMDESTINATIONS, \VOLUME{01dd20558af6da83-d08afee5}\USERS\LABADMIN\APPDATA\ROAMING\MICROSOFT\WINDOWS\START MENU, \VOLUME{01dd20558af6da83-d08afee5}\USERS\LABADMIN\APPDATA\ROAMING\MICROSOFT\WINDOWS\START MENU\PROGRAMS, \VOLUME{01dd20558af6da83-d08afee5}\USERS\LABADMIN\APPDATA\ROAMING\MICROSOFT\WINDOWS\START MENU\PROGRAMS\WINDOWS POWERSHELL, \VOLUME{01dd20558af6da83-d08afee5}\USERS\LABADMIN\CONTACTS, \VOLUME{01dd20558af6da83-d08afee5}\USERS\LABADMIN\DESKTOP, \VOLUME{01dd20558af6da83-d08afee5}\USERS\LABADMIN\DOCUMENTS, \VOLUME{01dd20558af6da83-d08afee5}\USERS\LABADMIN\DOWNLOADS, \VOLUME{01dd20558af6da83-d08afee5}\USERS\LABADMIN\LINKS, \VOLUME{01dd20558af6da83-d08afee5}\USERS\LABADMIN\MUSIC, \VOLUME{01dd20558af6da83-d08afee5}\USERS\LABADMIN\ONEDRIVE, \VOLUME{01dd20558af6da83-d08afee5}\USERS\LABADMIN\PICTURES, \VOLUME{01dd20558af6da83-d08afee5}\USERS\LABADMIN\SAVED GAMES, \VOLUME{01dd20558af6da83-d08afee5}\USERS\LABADMIN\SEARCHES, \VOLUME{01dd20558af6da83-d08afee5}\USERS\LABADMIN\VIDEOS, \VOLUME{01dd20558af6da83-d08afee5}\WINDOWS, \VOLUME{01dd20558af6da83-d08afee5}\WINDOWS\ASSEMBLY, \VOLUME{01dd20558af6da83-d08afee5}\WINDOWS\ASSEMBLY\NATIVEIMAGES_V4.0.30319_64, \VOLUME{01dd20558af6da83-d08afee5}\WINDOWS\ASSEMBLY\NATIVEIMAGES_V4.0.30319_64\MICROSOFT.MF49F6405#, \VOLUME{01dd20558af6da83-d08afee5}\WINDOWS\ASSEMBLY\NATIVEIMAGES_V4.0.30319_64\MICROSOFT.MF49F6405#\26CAF7C6CD61C21D731AD51C3C0B4692, \VOLUME{01dd20558af6da83-d08afee5}\WINDOWS\ASSEMBLY\NATIVEIMAGES_V4.0.30319_64\MICROSOFT.P6F792626#, \VOLUME{01dd20558af6da83-d08afee5}\WINDOWS\ASSEMBLY\NATIVEIMAGES_V4.0.30319_64\MICROSOFT.P6F792626#\381003111201B9E93BAA7D91C94CA1BB, \VOLUME{01dd20558af6da83-d08afee5}\WINDOWS\ASSEMBLY\NATIVEIMAGES_V4.0.30319_64\MICROSOFT.PB378EC07#, \VOLUME{01dd20558af6da83-d08afee5}\WINDOWS\ASSEMBLY\NATIVEIMAGES_V4.0.30319_64\MICROSOFT.PB378EC07#\96F748786DB96E4095B0A0402A3CFCAE, \VOLUME{01dd20558af6da83-d08afee5}\WINDOWS\ASSEMBLY\NATIVEIMAGES_V4.0.30319_64\MSCORLIB, \VOLUME{01dd20558af6da83-d08afee5}\WINDOWS\ASSEMBLY\NATIVEIMAGES_V4.0.30319_64\MSCORLIB\3452D280CF55AE309A9FFBE81EA33A15, \VOLUME{01dd20558af6da83-d08afee5}\WINDOWS\ASSEMBLY\NATIVEIMAGES_V4.0.30319_64\SYSTEM, \VOLUME{01dd20558af6da83-d08afee5}\WINDOWS\ASSEMBLY\NATIVEIMAGES_V4.0.30319_64\SYSTEM.CONFIGURATION, \VOLUME{01dd20558af6da83-d08afee5}\WINDOWS\ASSEMBLY\NATIVEIMAGES_V4.0.30319_64\SYSTEM.CONFIGURATION\EA379F2C8031866EF105C9BC09EBB71F, \VOLUME{01dd20558af6da83-d08afee5}\WINDOWS\ASSEMBLY\NATIVEIMAGES_V4.0.30319_64\SYSTEM.CORE, \VOLUME{01dd20558af6da83-d08afee5}\WINDOWS\ASSEMBLY\NATIVEIMAGES_V4.0.30319_64\SYSTEM.CORE\0F70710D98654B6EB0F31C3CA310325D, \VOLUME{01dd20558af6da83-d08afee5}\WINDOWS\ASSEMBLY\NATIVEIMAGES_V4.0.30319_64\SYSTEM.DATA, \VOLUME{01dd20558af6da83-d08afee5}\WINDOWS\ASSEMBLY\NATIVEIMAGES_V4.0.30319_64\SYSTEM.DATA\731DF61DCC7CAEA81C53AE5663E87341, \VOLUME{01dd20558af6da83-d08afee5}\WINDOWS\ASSEMBLY\NATIVEIMAGES_V4.0.30319_64\SYSTEM.DIRED13B18A9#, \VOLUME{01dd20558af6da83-d08afee5}\WINDOWS\ASSEMBLY\NATIVEIMAGES_V4.0.30319_64\SYSTEM.DIRED13B18A9#\76A6F5B3696804F9492E9CF10ED3D90E, \VOLUME{01dd20558af6da83-d08afee5}\WINDOWS\ASSEMBLY\NATIVEIMAGES_V4.0.30319_64\SYSTEM.MANAA57FC8CC#, \VOLUME{01dd20558af6da83-d08afee5}\WINDOWS\ASSEMBLY\NATIVEIMAGES_V4.0.30319_64\SYSTEM.MANAA57FC8CC#\A5059CABEE51B63CA636D3C567A63E6E, \VOLUME{01dd20558af6da83-d08afee5}\WINDOWS\ASSEMBLY\NATIVEIMAGES_V4.0.30319_64\SYSTEM.MANAGEMENT, \VOLUME{01dd20558af6da83-d08afee5}\WINDOWS\ASSEMBLY\NATIVEIMAGES_V4.0.30319_64\SYSTEM.MANAGEMENT\FD57ADD249214512518DFD4C91126290, \VOLUME{01dd20558af6da83-d08afee5}\WINDOWS\ASSEMBLY\NATIVEIMAGES_V4.0.30319_64\SYSTEM.TRANSACTIONS, \VOLUME{01dd20558af6da83-d08afee5}\WINDOWS\ASSEMBLY\NATIVEIMAGES_V4.0.30319_64\SYSTEM.TRANSACTIONS\E11F704F862F782FBF1F8EAD40CD771A, \VOLUME{01dd20558af6da83-d08afee5}\WINDOWS\ASSEMBLY\NATIVEIMAGES_V4.0.30319_64\SYSTEM.XML, \VOLUME{01dd20558af6da83-d08afee5}\WINDOWS\ASSEMBLY\NATIVEIMAGES_V4.0.30319_64\SYSTEM.XML\C95D4C31D9E3487875DA6CC8F48489AE, \VOLUME{01dd20558af6da83-d08afee5}\WINDOWS\ASSEMBLY\NATIVEIMAGES_V4.0.30319_64\SYSTEM\2962E4ADB6482EE6FBABCB465600F685, \VOLUME{01dd20558af6da83-d08afee5}\WINDOWS\GLOBALIZATION, \VOLUME{01dd20558af6da83-d08afee5}\WINDOWS\GLOBALIZATION\SORTING, \VOLUME{01dd20558af6da83-d08afee5}\WINDOWS\MICROSOFT.NET, \VOLUME{01dd20558af6da83-d08afee5}\WINDOWS\MICROSOFT.NET\ASSEMBLY, \VOLUME{01dd20558af6da83-d08afee5}\WINDOWS\MICROSOFT.NET\ASSEMBLY\GAC_64, \VOLUME{01dd20558af6da83-d08afee5}\WINDOWS\MICROSOFT.NET\ASSEMBLY\GAC_64\SYSTEM.DATA, \VOLUME{01dd20558af6da83-d08afee5}\WINDOWS\MICROSOFT.NET\ASSEMBLY\GAC_64\SYSTEM.DATA\V4.0_4.0.0.0__B77A5C561934E089, \VOLUME{01dd20558af6da83-d08afee5}\WINDOWS\MICROSOFT.NET\ASSEMBLY\GAC_64\SYSTEM.TRANSACTIONS, \VOLUME{01dd20558af6da83-d08afee5}\WINDOWS\MICROSOFT.NET\ASSEMBLY\GAC_64\SYSTEM.TRANSACTIONS\V4.0_4.0.0.0__B77A5C561934E089, \VOLUME{01dd20558af6da83-d08afee5}\WINDOWS\MICROSOFT.NET\ASSEMBLY\GAC_MSIL, \VOLUME{01dd20558af6da83-d08afee5}\WINDOWS\MICROSOFT.NET\ASSEMBLY\GAC_MSIL\MICROSOFT.MANAGEMENT.INFRASTRUCTURE, \VOLUME{01dd20558af6da83-d08afee5}\WINDOWS\MICROSOFT.NET\ASSEMBLY\GAC_MSIL\MICROSOFT.MANAGEMENT.INFRASTRUCTURE\V4.0_1.0.0.0__31BF3856AD364E35, \VOLUME{01dd20558af6da83-d08afee5}\WINDOWS\MICROSOFT.NET\ASSEMBLY\GAC_MSIL\MICROSOFT.POWERSHELL.CONSOLEHOST, \VOLUME{01dd20558af6da83-d08afee5}\WINDOWS\MICROSOFT.NET\ASSEMBLY\GAC_MSIL\MICROSOFT.POWERSHELL.CONSOLEHOST\V4.0_3.0.0.0__31BF3856AD364E35, \VOLUME{01dd20558af6da83-d08afee5}\WINDOWS\MICROSOFT.NET\ASSEMBLY\GAC_MSIL\MICROSOFT.POWERSHELL.SECURITY, \VOLUME{01dd20558af6da83-d08afee5}\WINDOWS\MICROSOFT.NET\ASSEMBLY\GAC_MSIL\MICROSOFT.POWERSHELL.SECURITY\V4.0_3.0.0.0__31BF3856AD364E35, \VOLUME{01dd20558af6da83-d08afee5}\WINDOWS\MICROSOFT.NET\ASSEMBLY\GAC_MSIL\SYSTEM.MANAGEMENT.AUTOMATION, \VOLUME{01dd20558af6da83-d08afee5}\WINDOWS\MICROSOFT.NET\ASSEMBLY\GAC_MSIL\SYSTEM.MANAGEMENT.AUTOMATION\V4.0_3.0.0.0__31BF3856AD364E35, \VOLUME{01dd20558af6da83-d08afee5}\WINDOWS\MICROSOFT.NET\ASSEMBLY\GAC_MSIL\SYSTEM.NUMERICS, \VOLUME{01dd20558af6da83-d08afee5}\WINDOWS\MICROSOFT.NET\ASSEMBLY\GAC_MSIL\SYSTEM.NUMERICS\V4.0_4.0.0.0__B77A5C561934E089, \VOLUME{01dd20558af6da83-d08afee5}\WINDOWS\MICROSOFT.NET\FRAMEWORK, \VOLUME{01dd20558af6da83-d08afee5}\WINDOWS\MICROSOFT.NET\FRAMEWORK64, \VOLUME{01dd20558af6da83-d08afee5}\WINDOWS\MICROSOFT.NET\FRAMEWORK64\V4.0.30319, \VOLUME{01dd20558af6da83-d08afee5}\WINDOWS\MICROSOFT.NET\FRAMEWORK64\V4.0.30319\CONFIG, \VOLUME{01dd20558af6da83-d08afee5}\WINDOWS\MICROSOFT.NET\FRAMEWORK\V4.0.30319, \VOLUME{01dd20558af6da83-d08afee5}\WINDOWS\REGISTRATION, \VOLUME{01dd20558af6da83-d08afee5}\WINDOWS\SYSTEM32, \VOLUME{01dd20558af6da83-d08afee5}\WINDOWS\SYSTEM32\CATROOT, \VOLUME{01dd20558af6da83-d08afee5}\WINDOWS\SYSTEM32\CATROOT\{F750E6C3-38EE-11D1-85E5-00C04FC295EE}, \VOLUME{01dd20558af6da83-d08afee5}\WINDOWS\SYSTEM32\EN-US, \VOLUME{01dd20558af6da83-d08afee5}\WINDOWS\SYSTEM32\WINDOWSPOWERSHELL, \VOLUME{01dd20558af6da83-d08afee5}\WINDOWS\SYSTEM32\WINDOWSPOWERSHELL\V1.0, \VOLUME{01dd20558af6da83-d08afee5}\WINDOWS\SYSTEM32\WINDOWSPOWERSHELL\V1.0\EN-US, \VOLUME{01dd20558af6da83-d08afee5}\WINDOWS\SYSTEM32\WINDOWSPOWERSHELL\V1.0\MODULES, \VOLUME{01dd20558af6da83-d08afee5}\WINDOWS\SYSTEM32\WINDOWSPOWERSHELL\V1.0\MODULES\MICROSOFT.POWERSHELL.MANAGEMENT, \VOLUME{01dd20558af6da83-d08afee5}\WINDOWS\SYSTEM32\WINDOWSPOWERSHELL\V1.0\MODULES\MICROSOFT.POWERSHELL.UTILITY, \VOLUME{01dd20558af6da83-d08afee5}\WINDOWS\WINSXS\AMD64_SYSTEM.DATA.SQLXML_B77A5C561934E089_4.0.15920.119_NONE_83439DB3CB58899A, \VOLUME{01dd20558af6da83-d08afee5}\WINDOWS\WINSXS\AMD64_SYSTEM.DIRECTORYSERVICES_B03F5F7F11D50A3A_4.0.15920.100_NONE_A860A5D757D37792, \VOLUME{01dd20558af6da83-d08afee5}\WINDOWS\WINSXS\AMD64_SYSTEM.ENTERPRISESERVICES_B03F5F7F11D50A3A_4.0.15920.100_NONE_2768E327D47891AC, \VOLUME{01dd20558af6da83-d08afee5}\WINDOWS\WINSXS\CATALOGS, \VOLUME{01dd20558af6da83-d08afee5}\USERS\LABADMIN\APPDATA\ROAMING\MICROSOFT\WINDOWS\POWERSHELL, \VOLUME{01dd20558af6da83-d08afee5}\USERS\LABADMIN\APPDATA\ROAMING\MICROSOFT\WINDOWS\POWERSHELL\PSREADLINE, \VOLUME{01dd20558af6da83-d08afee5}\WINDOWS\ASSEMBLY\NATIVEIMAGES_V4.0.30319_64\MICROSOFT.PAE3498D9#, \VOLUME{01dd20558af6da83-d08afee5}\WINDOWS\ASSEMBLY\NATIVEIMAGES_V4.0.30319_64\MICROSOFT.PAE3498D9#\218ADA55D0662B02D4C67DF6B332E489, \VOLUME{01dd20558af6da83-d08afee5}\WINDOWS\ASSEMBLY\NATIVEIMAGES_V4.0.30319_64\SYSTEM.CONFE64A9051#, \VOLUME{01dd20558af6da83-d08afee5}\WINDOWS\ASSEMBLY\NATIVEIMAGES_V4.0.30319_64\SYSTEM.CONFE64A9051#\4F44EE5C66D31D24EB1DBE2D52F3F677, \VOLUME{01dd20558af6da83-d08afee5}\WINDOWS\ASSEMBLY\NATIVEIMAGES_V4.0.30319_64\SYSTEM.DRAWING, \VOLUME{01dd20558af6da83-d08afee5}\WINDOWS\ASSEMBLY\NATIVEIMAGES_V4.0.30319_64\SYSTEM.DRAWING\A7773EDDE31D2D5C70A2C9F3DD56E283, \VOLUME{01dd20558af6da83-d08afee5}\WINDOWS\ASSEMBLY\NATIVEIMAGES_V4.0.30319_64\SYSTEM.SERV759BFB78#, \VOLUME{01dd20558af6da83-d08afee5}\WINDOWS\ASSEMBLY\NATIVEIMAGES_V4.0.30319_64\SYSTEM.SERV759BFB78#\E7253AFC5056A1BA48C382E8806D6CF7, \VOLUME{01dd20558af6da83-d08afee5}\WINDOWS\ASSEMBLY\NATIVEIMAGES_V4.0.30319_64\SYSTEM.WINDOWS.FORMS, \VOLUME{01dd20558af6da83-d08afee5}\WINDOWS\ASSEMBLY\NATIVEIMAGES_V4.0.30319_64\SYSTEM.WINDOWS.FORMS\DCD36ECC9F4807AE6091D89B21B70BD8, \VOLUME{01dd20558af6da83-d08afee5}\WINDOWS\MICROSOFT.NET\ASSEMBLY\GAC_64\MICROSOFT.APPV.APPVCLIENTCOMCONSUMER, \VOLUME{01dd20558af6da83-d08afee5}\WINDOWS\MICROSOFT.NET\ASSEMBLY\GAC_64\MICROSOFT.APPV.APPVCLIENTCOMCONSUMER\V4.0_10.0.0.0__31BF3856AD364E35, \VOLUME{01dd20558af6da83-d08afee5}\WINDOWS\MICROSOFT.NET\ASSEMBLY\GAC_64\MICROSOFT.KEYDISTRIBUTIONSERVICE.CMDLETS, \VOLUME{01dd20558af6da83-d08afee5}\WINDOWS\MICROSOFT.NET\ASSEMBLY\GAC_64\MICROSOFT.KEYDISTRIBUTIONSERVICE.CMDLETS\V4.0_10.0.0.0__31BF3856AD364E35, \VOLUME{01dd20558af6da83-d08afee5}\WINDOWS\MICROSOFT.NET\ASSEMBLY\GAC_64\MICROSOFT.MANAGEMENT.INFRASTRUCTURE.NATIVE, \VOLUME{01dd20558af6da83-d08afee5}\WINDOWS\MICROSOFT.NET\ASSEMBLY\GAC_64\MICROSOFT.MANAGEMENT.INFRASTRUCTURE.NATIVE\V4.0_1.0.0.0__31BF3856AD364E35, \VOLUME{01dd20558af6da83-d08afee5}\WINDOWS\MICROSOFT.NET\ASSEMBLY\GAC_64\MICROSOFT.SECUREBOOT.COMMANDS, \VOLUME{01dd20558af6da83-d08afee5}\WINDOWS\MICROSOFT.NET\ASSEMBLY\GAC_64\MICROSOFT.SECUREBOOT.COMMANDS\V4.0_10.0.0.0__31BF3856AD364E35, \VOLUME{01dd20558af6da83-d08afee5}\WINDOWS\MICROSOFT.NET\ASSEMBLY\GAC_64\MICROSOFT.WINDOWSAUTHENTICATIONPROTOCOLS.COMMANDS, \VOLUME{01dd20558af6da83-d08afee5}\WINDOWS\MICROSOFT.NET\ASSEMBLY\GAC_64\MICROSOFT.WINDOWSAUTHENTICATIONPROTOCOLS.COMMANDS\V4.0_10.0.0.0__31BF3856AD364E35, \VOLUME{01dd20558af6da83-d08afee5}\WINDOWS\MICROSOFT.NET\ASSEMBLY\GAC_MSIL\MICROSOFT.CSHARP, \VOLUME{01dd20558af6da83-d08afee5}\WINDOWS\MICROSOFT.NET\ASSEMBLY\GAC_MSIL\MICROSOFT.CSHARP\V4.0_4.0.0.0__B03F5F7F11D50A3A, \VOLUME{01dd20558af6da83-d08afee5}\WINDOWS\MICROSOFT.NET\ASSEMBLY\GAC_MSIL\MICROSOFT.POWERSHELL.COMMANDS.MANAGEMENT, \VOLUME{01dd20558af6da83-d08afee5}\WINDOWS\MICROSOFT.NET\ASSEMBLY\GAC_MSIL\MICROSOFT.POWERSHELL.COMMANDS.MANAGEMENT\V4.0_3.0.0.0__31BF3856AD364E35, \VOLUME{01dd20558af6da83-d08afee5}\WINDOWS\MICROSOFT.NET\ASSEMBLY\GAC_MSIL\MICROSOFT.WINDOWS.APPX.PACKAGEMANAGER.COMMANDS, \VOLUME{01dd20558af6da83-d08afee5}\WINDOWS\MICROSOFT.NET\ASSEMBLY\GAC_MSIL\MICROSOFT.WINDOWS.APPX.PACKAGEMANAGER.COMMANDS\V4.0_10.0.0.0__31BF3856AD364E35, \VOLUME{01dd20558af6da83-d08afee5}\WINDOWS\MICROSOFT.NET\ASSEMBLY\GAC_MSIL\MICROSOFT.WINDOWS.STARTLAYOUT.COMMANDS, \VOLUME{01dd20558af6da83-d08afee5}\WINDOWS\MICROSOFT.NET\ASSEMBLY\GAC_MSIL\MICROSOFT.WINDOWS.STARTLAYOUT.COMMANDS\V4.0_10.0.0.0__31BF3856AD364E35, \VOLUME{01dd20558af6da83-d08afee5}\WINDOWS\MICROSOFT.NET\ASSEMBLY\GAC_MSIL\SYSTEM.DIRECTORYSERVICES, \VOLUME{01dd20558af6da83-d08afee5}\WINDOWS\MICROSOFT.NET\ASSEMBLY\GAC_MSIL\SYSTEM.DIRECTORYSERVICES\V4.0_4.0.0.0__B03F5F7F11D50A3A, \VOLUME{01dd20558af6da83-d08afee5}\WINDOWS\MICROSOFT.NET\ASSEMBLY\GAC_MSIL\SYSTEM.DYNAMIC, \VOLUME{01dd20558af6da83-d08afee5}\WINDOWS\MICROSOFT.NET\ASSEMBLY\GAC_MSIL\SYSTEM.DYNAMIC\V4.0_4.0.0.0__B03F5F7F11D50A3A, \VOLUME{01dd20558af6da83-d08afee5}\WINDOWS\MICROSOFT.NET\ASSEMBLY\GAC_MSIL\SYSTEM.MANAGEMENT, \VOLUME{01dd20558af6da83-d08afee5}\WINDOWS\MICROSOFT.NET\ASSEMBLY\GAC_MSIL\SYSTEM.MANAGEMENT\V4.0_4.0.0.0__B03F5F7F11D50A3A, \VOLUME{01dd20558af6da83-d08afee5}\WINDOWS\SYSTEM32\WINDOWSPOWERSHELL\V1.0\MODULES\APPVCLIENT, \VOLUME{01dd20558af6da83-d08afee5}\WINDOWS\SYSTEM32\WINDOWSPOWERSHELL\V1.0\MODULES\BITLOCKER, \VOLUME{01dd20558af6da83-d08afee5}\WINDOWS\SYSTEM32\WINDOWSPOWERSHELL\V1.0\MODULES\MICROSOFT.POWERSHELL.LOCALACCOUNTS, \VOLUME{01dd20558af6da83-d08afee5}\WINDOWS\SYSTEM32\WINDOWSPOWERSHELL\V1.0\MODULES\MICROSOFT.POWERSHELL.LOCALACCOUNTS\1.0.0.0, \VOLUME{01dd20558af6da83-d08afee5}\WINDOWS\SYSTEM32\WINDOWSPOWERSHELL\V1.0\MODULES\UEV, \VOLUME{01dd20558af6da83-d08afee5}\WINDOWS\SYSTEM32\WINDOWSPOWERSHELL\V1.0\MODULES\WHEA, \VOLUME{01dd20558af6da83-d08afee5}\WINDOWS\SYSTEM32\WINDOWSPOWERSHELL\V1.0\MODULES\WINDOWSERRORREPORTING, \VOLUME{01dd20558af6da83-d08afee5}\WINDOWS\SYSTEM32\WINDOWSPOWERSHELL\V1.0\MODULES\WINDOWSSEARCH, \VOLUME{01dd20558af6da83-d08afee5}\WINDOWS\SYSTEM32\WINMETADATA, \VOLUME{01dd20558af6da83-d08afee5}\WINDOWS\WINSXS\AMD64_SYSTEM.RUNTIME.SERIALIZATION_B77A5C561934E089_4.0.15920.119_NONE_54315F0C0636E31F, \VOLUME{01dd20558af6da83-d08afee5}\WINDOWS\WINSXS\AMD64_SYSTEM.SERVICEPROCESS_B03F5F7F11D50A3A_4.0.15920.100_NONE_A6C03BD1A2F5ADDB | M2: False | N2: E:\KAPE_Runs\PS-A1-P0\PS-A1-P0-R01\KAPE\C\Windows\Prefetch\POWERSHELL.EXE-CA1AE517.pf
